<?xml version="1.0" ?>
<!-- =================================================================================== -->
<!-- |    This document was autogenerated by xacro from ridgeback.urdf.xacro           | -->
<!-- |    EDITING THIS FILE BY HAND IS NOT RECOMMENDED                                 | -->
<!-- =================================================================================== -->
<robot name="thing" xmlns:xacro="http://ros.org/wiki/xacro">
  <material name="dark_grey">
    <color rgba="0.2 0.2 0.2 1.0"/>
  </material>
  <material name="light_grey">
    <color rgba="0.4 0.4 0.4 1.0"/>
  </material>
  <material name="red">
    <color rgba="0.8 0.0 0.0 1.0"/>
  </material>
  <material name="white">
    <color rgba="0.9 0.9 0.9 1.0"/>
  </material>
  <material name="yellow">
    <color rgba="0.8 0.8 0.0 1.0"/>
  </material>
  <material name="black">
    <color rgba="0.15 0.15 0.15 1.0"/>
  </material>

  <!-- Ridgeback wheels -->
  <link name="front_rocker_link">
    <visual>
      <origin rpy="1.57079632679 0 1.57079632679" xyz="0 0 0"/>
      <geometry>
        <mesh filename="assets/ridgeback_description/meshes/rocker.stl"/>
      </geometry>
      <material name="black"/>
    </visual>
    <inertial>
      <origin rpy="1.57079632679 0 1.57079632679" xyz="0 0 0"/>
      <mass value="10.267"/>
      <inertia ixx="0.0288" ixy="2.20484e-6" ixz="-1.3145e-5" iyy="0.4324" iyz="1.8944e-3" izz="0.4130"/>
    </inertial>
  </link>
  <joint name="front_rocker" type="fixed">
    <parent link="axle_link"/>
    <child link="front_rocker_link"/>
    <origin rpy="0 0 0" xyz="0.319 0 0"/>
    <axis xyz="1 0 0"/>
    <limit effort="0" lower="-0.08726" upper="0.08726" velocity="0"/>
  </joint>
  <link name="front_left_wheel_link">
    <contact>
      <lateral_friction value="1.0"/>
      <rolling_friction value="0.0"/>
      <stiffness value="30000"/>
      <damping value="10000"/>
    </contact>
    <inertial>
      <origin rpy="0 0 0" xyz="0 0 0"/>
      <mass value="2.637"/>
      <!--<inertia ixx="3.3212e-3" ixy="0" ixz="0" iyy="6.6424e-3" iyz="0" izz="3.3212e-3"/>-->
      <inertia ixx="0.02467" ixy="0" ixz="0" iyy="0.02467" iyz="0" izz="0.04411"/>
    </inertial>
    <visual>
      <origin rpy="1.57079632679 0 0" xyz="0 0 0"/>
      <geometry>
        <mesh filename="assets/ridgeback_description/meshes/wheel.stl"/>
      </geometry>
      <material name="black"/>
    </visual>
    <collision>
      <origin rpy="1.57079632679 0 0" xyz="0 0 0"/>
      <geometry>
        <cylinder length="0.079" radius="0.0759"/>
      </geometry>
    </collision>
  </link>
  <joint name="front_left_wheel" type="continuous">
    <parent link="front_rocker_link"/>
    <child link="front_left_wheel_link"/>
    <origin rpy="0 0 0" xyz="0 0.2755 0"/>
    <axis xyz="0 1 0"/>
  </joint>
  <transmission name="front_wheel_trans">
    <type>transmission_interface/SimpleTransmission</type>
    <joint name="front_left_wheel">
      <hardwareInterface>hardware_interface/VelocityJointInterface</hardwareInterface>
    </joint>
    <actuator name="front_left_actuator">
      <mechanicalReduction>1</mechanicalReduction>
    </actuator>
  </transmission>
  <link name="front_right_wheel_link">
    <contact>
      <lateral_friction value="1.0"/>
      <rolling_friction value="0.0"/>
      <stiffness value="30000"/>
      <damping value="10000"/>
    </contact>
    <inertial>
      <origin rpy="0 0 0" xyz="0 0 0"/>
      <mass value="2.637"/>
      <!--<inertia ixx="3.3212e-3" ixy="0" ixz="0" iyy="6.6424e-3" iyz="0" izz="3.3212e-3"/>-->
      <inertia ixx="0.02467" ixy="0" ixz="0" iyy="0.02467" iyz="0" izz="0.04411"/>
    </inertial>
    <visual>
      <origin rpy="1.57079632679 0 0" xyz="0 0 0"/>
      <geometry>
        <mesh filename="assets/ridgeback_description/meshes/wheel.stl"/>
      </geometry>
      <material name="black"/>
    </visual>
    <collision>
      <origin rpy="1.57079632679 0 0" xyz="0 0 0"/>
      <geometry>
        <cylinder length="0.079" radius="0.0759"/>
      </geometry>
    </collision>
  </link>
  <joint name="front_right_wheel" type="continuous">
    <parent link="front_rocker_link"/>
    <child link="front_right_wheel_link"/>
    <origin rpy="0 0 0" xyz="0 -0.2755 0"/>
    <axis xyz="0 1 0"/>
  </joint>
  <transmission name="front_wheel_trans">
    <type>transmission_interface/SimpleTransmission</type>
    <joint name="front_right_wheel">
      <hardwareInterface>hardware_interface/VelocityJointInterface</hardwareInterface>
    </joint>
    <actuator name="front_right_actuator">
      <mechanicalReduction>1</mechanicalReduction>
    </actuator>
  </transmission>
  <link name="rear_rocker_link">
    <visual>
      <origin rpy="1.57079632679 0 1.57079632679" xyz="0 0 0"/>
      <geometry>
        <mesh filename="assets/ridgeback_description/meshes/rocker.stl"/>
      </geometry>
      <material name="black"/>
    </visual>
    <inertial>
      <origin rpy="1.57079632679 0 1.57079632679" xyz="0 0 0"/>
      <mass value="10.267"/>
      <inertia ixx="0.0288" ixy="2.20484e-6" ixz="-1.3145e-5" iyy="0.4324" iyz="1.8944e-3" izz="0.4130"/>
    </inertial>
  </link>
  <joint name="rear_rocker" type="fixed">
    <parent link="axle_link"/>
    <child link="rear_rocker_link"/>
    <origin rpy="0 0 0" xyz="-0.319 0 0"/>
    <axis xyz="1 0 0"/>
    <limit effort="0" velocity="0"/>
  </joint>
  <link name="rear_left_wheel_link">
    <contact>
      <lateral_friction value="1.0"/>
      <rolling_friction value="0.0"/>
      <stiffness value="30000"/>
      <damping value="10000"/>
    </contact>
    <inertial>
      <origin rpy="0 0 0" xyz="0 0 0"/>
      <mass value="2.637"/>
      <!--<inertia ixx="3.3212e-3" ixy="0" ixz="0" iyy="6.6424e-3" iyz="0" izz="3.3212e-3"/>-->
      <inertia ixx="0.02467" ixy="0" ixz="0" iyy="0.02467" iyz="0" izz="0.04411"/>
    </inertial>
    <visual>
      <origin rpy="1.57079632679 0 0" xyz="0 0 0"/>
      <geometry>
        <mesh filename="assets/ridgeback_description/meshes/wheel.stl"/>
      </geometry>
      <material name="black"/>
    </visual>
    <collision>
      <origin rpy="1.57079632679 0 0" xyz="0 0 0"/>
      <geometry>
        <cylinder length="0.079" radius="0.0759"/>
      </geometry>
    </collision>
  </link>
  <joint name="rear_left_wheel" type="continuous">
    <parent link="rear_rocker_link"/>
    <child link="rear_left_wheel_link"/>
    <origin rpy="0 0 0" xyz="0 0.2755 0"/>
    <axis xyz="0 1 0"/>
  </joint>
  <transmission name="rear_wheel_trans">
    <type>transmission_interface/SimpleTransmission</type>
    <joint name="rear_left_wheel">
      <hardwareInterface>hardware_interface/VelocityJointInterface</hardwareInterface>
    </joint>
    <actuator name="rear_left_actuator">
      <mechanicalReduction>1</mechanicalReduction>
    </actuator>
  </transmission>
  <link name="rear_right_wheel_link">
    <contact>
      <lateral_friction value="1.0"/>
      <rolling_friction value="0.0"/>
      <stiffness value="30000"/>
      <damping value="10000"/>
    </contact>
    <inertial>
      <origin rpy="0 0 0" xyz="0 0 0"/>
      <mass value="2.637"/>
      <!--<inertia ixx="3.3212e-3" ixy="0" ixz="0" iyy="6.6424e-3" iyz="0" izz="3.3212e-3"/>-->
      <inertia ixx="0.02467" ixy="0" ixz="0" iyy="0.02467" iyz="0" izz="0.04411"/>
    </inertial>
    <visual>
      <origin rpy="1.57079632679 0 0" xyz="0 0 0"/>
      <geometry>
        <mesh filename="assets/ridgeback_description/meshes/wheel.stl"/>
      </geometry>
      <material name="black"/>
    </visual>
    <collision>
      <origin rpy="1.57079632679 0 0" xyz="0 0 0"/>
      <geometry>
        <cylinder length="0.079" radius="0.0759"/>
      </geometry>
    </collision>
  </link>
  <joint name="rear_right_wheel" type="continuous">
    <parent link="rear_rocker_link"/>
    <child link="rear_right_wheel_link"/>
    <origin rpy="0 0 0" xyz="0 -0.2755 0"/>
    <axis xyz="0 1 0"/>
  </joint>
  <transmission name="rear_wheel_trans">
    <type>transmission_interface/SimpleTransmission</type>
    <joint name="rear_right_wheel">
      <hardwareInterface>hardware_interface/VelocityJointInterface</hardwareInterface>
    </joint>
    <actuator name="rear_right_actuator">
      <mechanicalReduction>1</mechanicalReduction>
    </actuator>
  </transmission>
  <link name="base_link"/>
  <joint name="base_link_joint" type="fixed">
    <origin rpy="0 0 0" xyz="0 0 0"/>
    <parent link="base_link"/>
    <child link="chassis_link"/>
  </joint>
  <link name="chassis_link">
    <visual>
      <origin rpy="0 0 0" xyz="0 0 0"/>
      <geometry>
        <mesh filename="assets/ridgeback_description/meshes/body.stl"/>
      </geometry>
      <material name="black"/>
    </visual>
    <collision>
      <origin xyz="0 0 0"/>
      <geometry>
        <mesh filename="assets/ridgeback_description/meshes/body-collision.stl"/>
      </geometry>
    </collision>
    <inertial>
      <origin rpy="1.57079632679 0 1.57079632679" xyz="0.012 0.002 0.067"/>
      <mass value="165.304"/>
      <inertia ixx="4.4744" ixy="0.03098" ixz="0.003647" iyy="7.1624" iyz="0.1228" izz="4.6155"/>
    </inertial>
  </link>
  <joint name="right_side_cover_link_joint" type="fixed">
    <origin rpy="0 0 0" xyz="0 0 0"/>
    <parent link="chassis_link"/>
    <child link="right_side_cover_link"/>
  </joint>
  <joint name="left_side_cover_link_joint" type="fixed">
    <origin rpy="0 0 0" xyz="0 0 0"/>
    <parent link="chassis_link"/>
    <child link="left_side_cover_link"/>
  </joint>
  <link name="left_side_cover_link">
    <visual>
      <origin rpy="0 0 3.14159265359" xyz="0 0 0"/>
      <geometry>
        <mesh filename="assets/ridgeback_description/meshes/side-cover.stl"/>
      </geometry>
      <material name="yellow"/>
    </visual>
  </link>
  <link name="right_side_cover_link">
    <visual>
      <origin rpy="0 0 0" xyz="0 0 0"/>
      <geometry>
        <mesh filename="assets/ridgeback_description/meshes/side-cover.stl"/>
      </geometry>
      <material name="yellow"/>
    </visual>
  </link>
  <joint name="front_cover_link_joint" type="fixed">
    <origin rpy="0 0 0" xyz="0 0 0"/>
    <parent link="chassis_link"/>
    <child link="front_cover_link"/>
  </joint>
  <link name="front_cover_link">
    <visual>
      <origin rpy="0 0 0" xyz="0 0 0"/>
      <geometry>
        <mesh filename="assets/ridgeback_description/meshes/end-cover.stl"/>
      </geometry>
      <material name="black"/>
    </visual>
  </link>
  <joint name="rear_cover_link_joint" type="fixed">
    <origin rpy="0 0 0" xyz="0 0 0"/>
    <parent link="chassis_link"/>
    <child link="rear_cover_link"/>
  </joint>
  <link name="rear_cover_link">
    <visual>
      <origin rpy="0 0 3.14159265359" xyz="0 0 0"/>
      <geometry>
        <mesh filename="assets/ridgeback_description/meshes/end-cover.stl"/>
      </geometry>
      <material name="black"/>
    </visual>
  </link>
  <joint name="front_lights_link_joint" type="fixed">
    <origin rpy="0 0 0" xyz="0 0 0"/>
    <parent link="chassis_link"/>
    <child link="front_lights_link"/>
  </joint>
  <joint name="rear_lights_link_joint" type="fixed">
    <origin rpy="0 0 0" xyz="0 0 0"/>
    <parent link="chassis_link"/>
    <child link="rear_lights_link"/>
  </joint>
  <link name="front_lights_link">
    <visual>
      <origin rpy="0 0 0" xyz="0 0 0"/>
      <geometry>
        <mesh filename="assets/ridgeback_description/meshes/lights.stl"/>
      </geometry>
      <material name="white"/>
    </visual>
  </link>
  <link name="rear_lights_link">
    <visual>
      <origin rpy="0 0 3.14159265359" xyz="0 0 0"/>
      <geometry>
        <mesh filename="assets/ridgeback_description/meshes/lights.stl"/>
      </geometry>
      <material name="red"/>
    </visual>
  </link>
  <joint name="top_link_joint" type="fixed">
    <origin rpy="0 0 0" xyz="0 0 0"/>
    <parent link="chassis_link"/>
    <child link="top_link"/>
  </joint>
  <link name="top_link">
    <visual>
      <origin rpy="0 0 0" xyz="0 0 0"/>
      <geometry>
        <mesh filename="assets/ridgeback_description/meshes/top.stl"/>
      </geometry>
      <material name="black"/>
    </visual>
    <collision>
      <origin rpy="0 0 0" xyz="0 0 0"/>
      <geometry>
        <mesh filename="assets/ridgeback_description/meshes/top.stl"/>
      </geometry>
    </collision>
  </link>
  <joint name="axle_joint" type="fixed">
    <origin rpy="0 0 0" xyz="0 0 0.05"/>
    <parent link="chassis_link"/>
    <child link="axle_link"/>
  </joint>
  <link name="axle_link">
    <visual>
      <origin rpy="0 1.57079632679 0" xyz="0 0 0"/>
      <geometry>
        <mesh filename="assets/ridgeback_description/meshes/axle.stl"/>
      </geometry>
      <material name="black"/>
    </visual>
  </link>
  <link name="imu_link">
    <inertial>
      <mass value="0.001"/>
      <origin rpy="0 0 0" xyz="0 0 0"/>
      <inertia ixx="1e-09" ixy="0.0" ixz="0.0" iyy="1e-09" iyz="0.0" izz="1e-09"/>
    </inertial>
  </link>
  <joint name="imu_joint" type="fixed">
    <parent link="chassis_link"/>
    <child link="imu_link"/>
    <origin rpy="0 0 0" xyz="0.2085 -0.2902 0.1681"/>
  </joint>
  <link name="mid_mount"/>
  <joint name="mid_mount_joint" type="fixed">
    <parent link="base_link"/>
    <child link="mid_mount"/>
    <origin rpy="0 0 0" xyz="0 0 0.28"/>
  </joint>

  <link name="arch_link">
  <visual>
    <origin rpy="1.570795 0 0" xyz="0.0 0.0 0.0"/>
    <geometry>
      <mesh filename="assets/ridgeback_description/meshes/tor11_mech.stl" />
    </geometry>
    <material name="light_grey"/>
  </visual>
  <collision>
    <origin rpy="1.570795 0 0" xyz="0.0 0.0 0.0"/>
    <geometry>
      <mesh filename="assets/ridgeback_description/meshes/tor11_mech.stl" />
    </geometry>
  </collision>
 </link>

<joint name="arch_joint" type="fixed">
  <origin xyz="0 0 0.278" rpy="0 0 1.57" />
  <parent link="top_link" />
  <child link="arch_link" />
</joint>

<!-- Join arm and arch link -->
<joint name="ur10_arm_base" type="fixed">
  <parent link="arch_link" />
  <child link="ur10_base_link" />
  <origin xyz="0.01 -0.27 0.375" rpy="0.0 0.0 1.570796" />
</joint>

<!-- common stuff -->
<material name="blackish">
  <color rgba="0.2 0.2 0.2 1"/>
</material>
<material name="LightGrey">
  <color rgba="0.7 0.7 0.7 1.0"/>
</material>
<material name="LightBlue">
  <color rgba="0.670 0.815 0.921 1.0"/>
</material>

<link name="ur10_base_link">
  <visual>
    <origin xyz="0 0 0" rpy="1.57 0 0"/>
    <geometry>
      <mesh filename="assets/ur_description/meshes/ur10/visual/Base.obj"/>
    </geometry>
    <material name="LightGrey"/>
  </visual>
  <collision>
    <geometry>
      <mesh filename="assets/ur_description/meshes/ur10/collision/base.stl"/>
    </geometry>
  </collision>
  <inertial>
    <mass value="4.0"/>
    <origin rpy="0 0 0" xyz="0.0 0.0 0.0"/>
    <inertia ixx="0.0061063308908" ixy="0.0" ixz="0.0" iyy="0.0061063308908" iyz="0.0" izz="0.01125"/>
  </inertial>
</link>
<joint name="shoulder_pan_joint" type="revolute">
  <parent link="ur10_base_link"/>
  <child link="shoulder_link"/>
  <origin rpy="0.0 0.0 0.0" xyz="0.0 0.0 0.1273"/>
  <axis xyz="0 0 1"/>
  <limit effort="330.0" lower="-6.2831853" upper="6.2831853" velocity="2.16"/>
  <dynamics damping="0.0" friction="0.0"/>
</joint>
<link name="shoulder_link">
  <visual>
    <origin xyz="0 0 0" rpy="1.57 0 0"/>
    <geometry>
      <mesh filename="assets/ur_description/meshes/ur10/visual/Shoulder.obj"/>
    </geometry>
    <material name="LightGrey"/>
  </visual>
  <collision>
    <geometry>
      <mesh filename="assets/ur_description/meshes/ur10/collision/shoulder.stl"/>
    </geometry>
  </collision>
  <inertial>
    <mass value="7.778"/>
    <origin rpy="0 0 0" xyz="0.0 0.0 0.0"/>
    <inertia ixx="0.0314743125769" ixy="0.0" ixz="0.0" iyy="0.0314743125769" iyz="0.0" izz="0.021875625"/>
  </inertial>
</link>
<joint name="shoulder_lift_joint" type="revolute">
  <parent link="shoulder_link"/>
  <child link="upper_arm_link"/>
  <origin rpy="0.0 1.570796325 0.0" xyz="0.0 0.220941 0.0"/>
  <axis xyz="0 1 0"/>
  <limit effort="330.0" lower="-6.2831853" upper="6.2831853" velocity="2.16"/>
  <dynamics damping="0.0" friction="0.0"/>
</joint>
<link name="upper_arm_link">
  <visual>
    <origin xyz="0 0 0" rpy="1.57 0 0"/>
    <geometry>
      <mesh filename="assets/ur_description/meshes/ur10/visual/UpperArm.obj"/>
    </geometry>
    <material name="LightGrey"/>
  </visual>
  <collision>
    <geometry>
      <mesh filename="assets/ur_description/meshes/ur10/collision/upper_arm.stl"/>
    </geometry>
  </collision>
  <inertial>
    <mass value="12.93"/>
    <origin rpy="0 0 0" xyz="0.0 0.0 0.306"/>
    <inertia ixx="0.421753803798" ixy="0.0" ixz="0.0" iyy="0.421753803798" iyz="0.0" izz="0.036365625"/>
  </inertial>
</link>
<joint name="elbow_joint" type="revolute">
  <parent link="upper_arm_link"/>
  <child link="forearm_link"/>
  <origin rpy="0.0 0.0 0.0" xyz="0.0 -0.1719 0.612"/>
  <axis xyz="0 1 0"/>
  <limit effort="150.0" lower="-6.2831853" upper="6.2831853" velocity="3.15"/>
  <dynamics damping="0.0" friction="0.0"/>
</joint>
<link name="forearm_link">
  <visual>
    <origin xyz="0 0 0" rpy="1.57 0 0"/>
    <geometry>
      <mesh filename="assets/ur_description/meshes/ur10/visual/Forearm.obj"/>
    </geometry>
    <material name="LightGrey"/>
  </visual>
  <collision>
    <geometry>
      <mesh filename="assets/ur_description/meshes/ur10/collision/forearm.stl"/>
    </geometry>
  </collision>
  <inertial>
    <mass value="3.87"/>
    <origin rpy="0 0 0" xyz="0.0 0.0 0.28615"/>
    <inertia ixx="0.111069694097" ixy="0.0" ixz="0.0" iyy="0.111069694097" iyz="0.0" izz="0.010884375"/>
  </inertial>
</link>
<joint name="wrist_1_joint" type="revolute">
  <parent link="forearm_link"/>
  <child link="wrist_1_link"/>
  <origin rpy="0.0 1.570796325 0.0" xyz="0.0 0.0 0.5723"/>
  <axis xyz="0 1 0"/>
  <limit effort="54.0" lower="-6.2831853" upper="6.2831853" velocity="3.2"/>
  <dynamics damping="0.0" friction="0.0"/>
</joint>
<link name="wrist_1_link">
  <visual>
    <origin xyz="0 0 0" rpy="1.57 0 0"/>
    <geometry>
      <mesh filename="assets/ur_description/meshes/ur10/visual/Wrist1.obj"/>
    </geometry>
    <material name="LightBlue"/>
  </visual>
  <collision>
    <geometry>
      <mesh filename="assets/ur_description/meshes/ur10/collision/wrist_1.stl"/>
    </geometry>
  </collision>
  <inertial>
    <mass value="1.96"/>
    <origin rpy="0 0 0" xyz="0.0 0.0 0.0"/>
    <inertia ixx="0.0051082479567" ixy="0.0" ixz="0.0" iyy="0.0051082479567" iyz="0.0" izz="0.0055125"/>
  </inertial>
</link>
<joint name="wrist_2_joint" type="revolute">
  <parent link="wrist_1_link"/>
  <child link="wrist_2_link"/>
  <origin rpy="0.0 0.0 0.0" xyz="0.0 0.1149 0.0"/>
  <axis xyz="0 0 1"/>
  <limit effort="54.0" lower="-6.2831853" upper="6.2831853" velocity="3.2"/>
  <dynamics damping="0.0" friction="0.0"/>
</joint>
<link name="wrist_2_link">
  <visual>
    <origin xyz="0 0 0" rpy="1.57 0 0"/>
    <geometry>
      <mesh filename="assets/ur_description/meshes/ur10/visual/Wrist2.obj"/>
    </geometry>
    <material name="LightGrey"/>
  </visual>
  <collision>
    <geometry>
      <mesh filename="assets/ur_description/meshes/ur10/collision/wrist_2.stl"/>
    </geometry>
  </collision>
  <inertial>
    <mass value="1.96"/>
    <origin rpy="0 0 0" xyz="0.0 0.0 0.0"/>
    <inertia ixx="0.0051082479567" ixy="0.0" ixz="0.0" iyy="0.0051082479567" iyz="0.0" izz="0.0055125"/>
  </inertial>
</link>
<joint name="wrist_3_joint" type="revolute">
  <parent link="wrist_2_link"/>
  <child link="wrist_3_link"/>
  <origin rpy="0.0 0.0 0.0" xyz="0.0 0.0 0.1157"/>
  <axis xyz="0 1 0"/>
  <limit effort="54.0" lower="-6.2831853" upper="6.2831853" velocity="3.2"/>
  <dynamics damping="0.0" friction="0.0"/>
</joint>
<link name="wrist_3_link">
  <visual>
    <origin xyz="0 0 0" rpy="1.57 0 0"/>
    <geometry>
      <mesh filename="assets/ur_description/meshes/ur10/visual/Wrist3.obj"/>
    </geometry>
    <material name="LightBlue"/>
  </visual>
  <collision>
    <geometry>
      <mesh filename="assets/ur_description/meshes/ur10/collision/wrist_3.stl"/>
    </geometry>
  </collision>
  <inertial>
    <mass value="0.202"/>
    <origin rpy="0 0 0" xyz="0.0 0.0 0.0"/>
    <inertia ixx="0.000526462289415" ixy="0.0" ixz="0.0" iyy="0.000526462289415" iyz="0.0" izz="0.000568125"/>
  </inertial>
</link>
<joint name="ee_fixed_joint" type="fixed">
  <parent link="wrist_3_link"/>
  <child link="ee_link"/>
  <origin rpy="0.0 0.0 0.0" xyz="0.0 0.0922 0.0"/>
</joint>
<link name="ee_link">
  <collision>
    <geometry>
      <box size="0.01 0.01 0.01"/>
    </geometry>
    <origin rpy="0 0 0" xyz="-0.01 0 0"/>
  </collision>
</link>

<!-- Gripper -->
  <joint name="robotiq_hand_joint" type="fixed">
   <x>4.5&gt;</x> 
   <parent link="ee_link"/> 
    <child link="palm"/>
  </joint>
  <!-- Insert the fingers -->
  <!-- Link list -->
  <!-- Link 0 -->
  <link name="finger_1_link_0">
    <visual>
      <origin rpy="0 0 0" xyz="0 0 0"/>
      <geometry>
        <mesh filename="package://robotiq_s_model_visualization/meshes/s-model_articulated/visual/link_0.STL"/>
      </geometry>
      <material name="green">
        <color rgba="0 1 0 1"/>
      </material>
    </visual>
    <collision>
      <origin rpy="0 0 0" xyz="0 0 0"/>
      <geometry>
        <mesh filename="package://robotiq_s_model_visualization/meshes/s-model_articulated/collision/link_0.STL"/>
      </geometry>
      <material name="yellow">
        <color rgba="0 1 1 1"/>
      </material>
    </collision>
    <inertial>
      <mass value="0.1"/>
      <origin xyz="-0.01 0 0"/>
      <inertia ixx="0.000018" ixy="0" ixz="0" iyy="0.000025" iyz="0" izz="0.000025"/>
    </inertial>
  </link>
  <gazebo reference="finger_1_link_0">
    <mu1>1.1</mu1>
    <mu2>1.1</mu2>
  </gazebo>
  <!-- Link 1 -->
  <link name="finger_1_link_1">
    <visual>
      <origin rpy="0 0 1.5708" xyz="0 0.05717 0"/>
      <geometry>
        <mesh filename="package://robotiq_s_model_visualization/meshes/s-model_articulated/visual/link_1.STL"/>
      </geometry>
      <material name="green"/>
    </visual>
    <collision>
      <origin rpy="0 0 1.5708" xyz="0 0.05717 0"/>
      <geometry>
        <mesh filename="package://robotiq_s_model_visualization/meshes/s-model_articulated/collision/link_1.STL"/>
      </geometry>
      <material name="yellow">
        <color rgba="0 1 1 1"/>
      </material>
    </collision>
    <inertial>
      <origin rpy="0 0 1.5708" xyz="0.00053 0.03218 0"/>
      <mass value="0.047"/>
      <inertia ixx="0.00000499332" ixy="0.00000091312" ixz="-0.00000000120" iyy="0.00006434531" iyz="-0.00000000007" izz="0.00006061917"/>
    </inertial>
  </link>
  <gazebo reference="finger_1_link_1">
    <mu1>1.1</mu1>
    <mu2>1.1</mu2>
  </gazebo>
  <!-- Link 2 -->
  <link name="finger_1_link_2">
    <visual>
      <origin rpy="0 0 1.5708" xyz="0 0.03810 0.0075"/>
      <geometry>
        <mesh filename="package://robotiq_s_model_visualization/meshes/s-model_articulated/visual/link_2.STL"/>
      </geometry>
      <material name="green"/>
    </visual>
    <collision>
      <origin rpy="0 0 1.5708" xyz="0 0.03810 0.0075"/>
      <geometry>
        <mesh filename="package://robotiq_s_model_visualization/meshes/s-model_articulated/collision/link_2.STL"/>
      </geometry>
      <material name="yellow"/>
    </collision>
    <inertial>
      <origin rpy="0 0 1.5708" xyz="0.00048 0.02167 0.00018"/>
      <mass value="0.03284"/>
      <inertia ixx="0.00000348008" ixy="0.00000031940" ixz="0.00000013041" iyy="0.00002248123" iyz="0.00000000291" izz="0.00001986346"/>
    </inertial>
  </link>
  <gazebo reference="finger_1_link_2">
    <mu1>1.1</mu1>
    <mu2>1.1</mu2>
  </gazebo>
  <!-- Link 3 -->
  <link name="finger_1_link_3">
    <visual>
      <origin rpy="0 0 0" xyz="0 0 0"/>
      <geometry>
        <mesh filename="package://robotiq_s_model_visualization/meshes/s-model_articulated/visual/link_3.STL"/>
      </geometry>
      <material name="green"/>
    </visual>
    <collision>
      <origin rpy="0 0 0" xyz="0 0 0"/>
      <geometry>
        <mesh filename="package://robotiq_s_model_visualization/meshes/s-model_articulated/collision/link_3.STL"/>
      </geometry>
      <material name="yellow"/>
    </collision>
    <inertial>
      <origin rpy="0 0 0" xyz="0.01626 0.00049 0.0002"/>
      <mass value="0.03354"/>
      <inertia ixx="0.00000305151" ixy="0.00000089792" ixz="0.00000000249" iyy="0.00001427978" iyz="-0.00000001191" izz="0.00001264126"/>
    </inertial>
  </link>
  <gazebo reference="finger_1_link_3">
    <mu1>1.1</mu1>
    <mu2>1.1</mu2>
  </gazebo>
  <!-- Link proximal actuating hinge -->
  <link name="finger_1_link_proximal_actuating_hinge">
    <visual>
      <origin rpy="0 0 0" xyz="0.01429 0 0"/>
      <geometry>
        <box size="0.02858 .0075 .002"/>
      </geometry>
    </visual>
    <collision>
      <origin rpy="0 0 0" xyz="0.01429 0 0"/>
      <geometry>
        <box size="0.02858 .0075 .002"/>
      </geometry>
    </collision>
    <inertial>
      <origin rpy="0 0 0" xyz="0.0012 -0.00162 -0.00161"/>
      <mass value="0.02647"/>
      <inertia ixx="0.00000156447" ixy="0.000000236226" ixz="-0.00000014862" iyy="0.00000221068" iyz="-0.00000014369" izz="0.00000323175"/>
    </inertial>
  </link>
  <gazebo reference="finger_1_link_proximal_actuating_hinge">
    <mu1>1.1</mu1>
    <mu2>1.1</mu2>
  </gazebo>
  <!-- Link paraproximal actuating hinge -->
  <link name="finger_1_link_paraproximal_actuating_hinge">
    <visual>
      <origin rpy="0 0 0" xyz="0.01143 0 0"/>
      <geometry>
        <box size="0.02286 .0075 .002"/>
      </geometry>
    </visual>
    <collision>
      <origin rpy="0 0 0" xyz="0.01143 0 0"/>
      <geometry>
        <box size="0.02286 .0075 .002"/>
      </geometry>
    </collision>
    <inertial>
      <origin rpy="0 0 0" xyz="0.0064 0 0"/>
      <!-- copied from proximal_actuating_hinge -->
      <mass value="0.00362"/>
      <inertia ixx="0.00000012043" ixy="0" ixz="0" iyy="0.00000053588" iyz="0" izz="0.00000065322"/>
    </inertial>
  </link>
  <gazebo reference="finger_1_link_paraproximal_actuating_hinge">
    <mu1>1.1</mu1>
    <mu2>1.1</mu2>
  </gazebo>
  <!-- Link proximal actuating bar -->
  <link name="finger_1_link_proximal_actuating_bar">
    <visual>
      <origin rpy="0 0 0" xyz="0.026789 0 0"/>
      <geometry>
        <box size="0.05398 .0075 .002"/>
      </geometry>
    </visual>
    <collision>
      <origin rpy="0 0 0" xyz="0.026789 0 0"/>
      <geometry>
        <box size="0.05398 .0075 .002"/>
      </geometry>
    </collision>
    <inertial>
      <origin rpy="0 0 0" xyz="0.02699 -0.00122 0"/>
      <mass value="0.00659"/>
      <inertia ixx="0.00000008348" ixy="-0.0000002179" ixz="0.00000000134" iyy="0.00000719076" iyz="0" izz="0.00000718272"/>
    </inertial>
  </link>
  <gazebo reference="finger_1_link_proximal_actuating_bar">
    <mu1>1.1</mu1>
    <mu2>1.1</mu2>
  </gazebo>
  <!-- Link paraproximal bar -->
  <link name="finger_1_link_paraproximal_bar">
    <visual>
      <origin rpy="0 0 0" xyz="0.02885 0 0"/>
      <geometry>
        <box size="0.05770 .0075 .002"/>
      </geometry>
    </visual>
    <collision>
      <origin rpy="0 0 0" xyz="0.02885 0 0"/>
      <geometry>
        <box size="0.05770 .0075 .002"/>
      </geometry>
    </collision>
    <inertial>
      <origin rpy="0 0 0" xyz="0.02858 -0.00129 0"/>
      <mass value="0.00732"/>
      <inertia ixx="0.00000009065" ixy="-0.00000027047" ixz="0.00000000142" iyy="0.00000878034" iyz="0" izz="0.00000877558"/>
    </inertial>
  </link>
  <gazebo reference="finger_1_link_paraproximal_bar">
    <mu1>1.1</mu1>
    <mu2>1.1</mu2>
  </gazebo>
  <!-- Link median actuating hinge -->
  <link name="finger_1_link_median_actuating_hinge">
    <visual>
      <origin rpy="0 0 0" xyz="0 0 0"/>
      <geometry>
        <box size=".02 .02 .002"/>
      </geometry>
    </visual>
    <collision>
      <origin rpy="0 0 0" xyz="0 0 0"/>
      <geometry>
        <box size=".02 .02 .002"/>
      </geometry>
    </collision>
    <inertial>
      <origin rpy="0 0 0" xyz="0.0092 0.00514 0"/>
      <mass value="0.00359"/>
      <inertia ixx="0.00000024735" ixy="0.00000023619" ixz="0" iyy="0.00000047681" iyz="0" izz="0.00000071813"/>
    </inertial>
  </link>
  <gazebo reference="finger_1_link_median_actuating_hinge">
    <mu1>1.1</mu1>
    <mu2>1.1</mu2>
  </gazebo>
  <!-- Link median bar -->
  <link name="finger_1_link_median_bar">
    <visual>
      <origin rpy="0 0 0" xyz="0.01905 0 0"/>
      <geometry>
        <box size="0.0381 .0075 .002"/>
      </geometry>
    </visual>
    <collision>
      <origin rpy="0 0 0" xyz="0.01905 0 0"/>
      <geometry>
        <box size="0.0381 .0075 .002"/>
      </geometry>
    </collision>
    <inertial>
      <origin rpy="0 0 0" xyz="0.01905 -0.00107 0"/>
      <mass value="0.00538"/>
      <inertia ixx="0.00000006639" ixy="-0.00000010996" ixz="0.00000000094" iyy="0.00000305318" iyz="0" izz="0.00000304657"/>
    </inertial>
  </link>
  <gazebo reference="finger_1_link_median_bar">
    <mu1>1.1</mu1>
    <mu2>1.1</mu2>
  </gazebo>
  <!-- Link paramedian hinge -->
  <link name="finger_1_link_paramedian_hinge">
    <visual>
      <origin rpy="0 0 0" xyz="0 0 0"/>
      <geometry>
        <box size=".02 .02 .002"/>
      </geometry>
    </visual>
    <collision>
      <origin rpy="0 0 0" xyz="0 0 0"/>
      <geometry>
        <box size=".02 .02 .002"/>
      </geometry>
    </collision>
    <inertial>
      <origin rpy="0 0 0" xyz="-0.01025 0.00046 0"/>
      <mass value="0.00276"/>
      <inertia ixx="0.00000004213" ixy="-0.00000001491" ixz="0" iyy="0.00000050258" iyz="0" izz="0.00000054007"/>
    </inertial>
  </link>
  <gazebo reference="finger_1_link_paramedian_hinge">
    <mu1>1.1</mu1>
    <mu2>1.1</mu2>
  </gazebo>
  <!-- Link median bar underactuated -->
  <link name="finger_1_link_median_bar_underactuated">
    <visual>
      <origin rpy="0 0 0" xyz="0.01905 0 0"/>
      <geometry>
        <box size="0.0381 .0075 .002"/>
      </geometry>
    </visual>
    <collision>
      <origin rpy="0 0 0" xyz="0.01905 0 0"/>
      <geometry>
        <box size="0.0381 .0075 .002"/>
      </geometry>
    </collision>
    <inertial>
      <origin rpy="0 0 0" xyz="0.01905 -0.00107 0"/>
      <mass value="0.00538"/>
      <inertia ixx="0.00000006639" ixy="-0.00000010996" ixz="-0.00000000094" iyy="0.00000305318" iyz="0" izz="0.00000304657"/>
    </inertial>
  </link>
  <gazebo reference="finger_1_link_median_bar_underactuated">
    <mu1>1.1</mu1>
    <mu2>1.1</mu2>
  </gazebo>
  <!-- Link paradistal hinge -->
  <link name="finger_1_link_paradistal_hinge">
    <visual>
      <origin rpy="0 0 0" xyz="0 0 0"/>
      <geometry>
        <box size=".02 .02 .002"/>
      </geometry>
    </visual>
    <collision>
      <origin rpy="0 0 0" xyz="0 0 0"/>
      <geometry>
        <box size=".02 0.02 .002"/>
      </geometry>
    </collision>
    <inertial>
      <origin rpy="0 0 0" xyz="0.00548 0 0"/>
      <mass value="0.00158"/>
      <inertia ixx="0.00000001907" ixy="0" ixz="0" iyy="0.00000010970" iyz="0" izz="0.00000012610"/>
    </inertial>
  </link>
  <gazebo reference="finger_1_link_paradistal_hinge">
    <mu1>1.1</mu1>
    <mu2>1.1</mu2>
  </gazebo>
  <!-- End of link list -->
  <!-- Joint list -->
  <!-- Joint proximal actuating hinge -->
  <joint name="finger_1_joint_proximal_actuating_hinge" type="revolute">
    <parent link="finger_1_link_0"/>
    <child link="finger_1_link_proximal_actuating_hinge"/>
    <axis xyz="0 0 1"/>
    <origin rpy="0 0 -2.0906" xyz="0 0 0.01"/>
    <limit effort="100" lower="-3.1416" upper="3.1416" velocity="100"/>
  </joint>
  <gazebo reference="finger_1_joint_proximal_actuating_hinge">
    <implicitSpringDamper>1</implicitSpringDamper>
  </gazebo>
  <!-- Joint paraproximal actuating hinge -->
  <joint name="finger_1_joint_paraproximal_actuating_hinge" type="revolute">
    <parent link="finger_1_link_0"/>
    <child link="finger_1_link_paraproximal_actuating_hinge"/>
    <axis xyz="0 0 1"/>
    <origin rpy="0 0 -2.0906" xyz="0 0 -0.01"/>
    <limit effort="100" lower="-3.1416" upper="3.1416" velocity="100"/>
  </joint>
  <gazebo reference="finger_1_joint_paraproximal_actuating_hinge">
    <implicitSpringDamper>1</implicitSpringDamper>
  </gazebo>
  <!-- Joint proximal actuating bar -->
  <joint name="finger_1_joint_proximal_actuating_bar" type="revolute">
    <parent link="finger_1_link_proximal_actuating_hinge"/>
    <child link="finger_1_link_proximal_actuating_bar"/>
    <axis xyz="0 0 1"/>
    <origin rpy="0 0 1.8616" xyz="0.02858 0 0"/>
    <limit effort="100" lower="-3.1416" upper="3.1416" velocity="100"/>
  </joint>
  <gazebo reference="finger_1_joint_proximal_actuating_bar">
    <implicitSpringDamper>1</implicitSpringDamper>
  </gazebo>
  <!-- Joint paraproximal bar -->
  <joint name="finger_1_joint_paraproximal_bar" type="revolute">
    <parent link="finger_1_link_paraproximal_actuating_hinge"/>
    <child link="finger_1_link_paraproximal_bar"/>
    <axis xyz="0 0 1"/>
    <origin rpy="0 0 1.57" xyz="0.02286 0 0"/>
    <limit effort="100" lower="-3.1416" upper="3.1416" velocity="100"/>
  </joint>
  <gazebo reference="finger_1_joint_paraproximal_bar">
    <implicitSpringDamper>1</implicitSpringDamper>
  </gazebo>
  <!-- Joint median actuating hinge -->
  <joint name="finger_1_joint_median_actuating_hinge" type="revolute">
    <parent link="finger_1_link_1"/>
    <child link="finger_1_link_median_actuating_hinge"/>
    <axis xyz="0 0 1"/>
    <origin rpy="0 0 -0.37" xyz="0 0.05715 0.01"/>
    <limit effort="100" lower="-3.1416" upper="3.1416" velocity="100"/>
  </joint>
  <gazebo reference="finger_1_joint_median_actuating_hinge">
    <implicitSpringDamper>1</implicitSpringDamper>
  </gazebo>
  <!-- Joint paramedian hinge -->
  <joint name="finger_1_joint_paramedian_hinge" type="revolute">
    <parent link="finger_1_link_1"/>
    <child link="finger_1_link_paramedian_hinge"/>
    <axis xyz="0 0 1"/>
    <!-- -0.37 is hand picked, 0.9719 is hand calculated from atan(0.02381/0.01625) -->
    <origin rpy="0 0 0" xyz="0 0.05715 -0.01"/>
    <limit effort="100" lower="-3.1416" upper="3.1416" velocity="100"/>
  </joint>
  <gazebo reference="finger_1_joint_paramedian_hinge">
    <implicitSpringDamper>1</implicitSpringDamper>
  </gazebo>
  <!-- Joint median actuating hinge median bar -->
  <joint name="finger_1_joint_median_actuating_hinge_median_bar" type="revolute">
    <parent link="finger_1_link_median_actuating_hinge"/>
    <child link="finger_1_link_median_bar"/>
    <axis xyz="0 0 1"/>
    <!-- hand calc 90 deg + atan(0.01516/0.01625) -->
    <origin rpy="0 0 2.3215" xyz="0.01625 0.01516 0"/>
    <limit effort="100" lower="-3.1416" upper="3.1416" velocity="100"/>
  </joint>
  <gazebo reference="finger_1_joint_median_actuating_hinge_median_bar">
    <implicitSpringDamper>1</implicitSpringDamper>
  </gazebo>
  <!-- Joint paradistal hinge -->
  <joint name="finger_1_joint_paradistal_hinge" type="revolute">
    <parent link="finger_1_link_2"/>
    <child link="finger_1_link_paradistal_hinge"/>
    <axis xyz="0 0 1"/>
    <origin rpy="0 0 0" xyz="0 0.039 -0.01"/>
    <limit effort="100" lower="-3.1416" upper="3.1416" velocity="100"/>
  </joint>
  <gazebo reference="finger_1_joint_paradistal_hinge">
    <implicitSpringDamper>1</implicitSpringDamper>
  </gazebo>
  <!-- Joint paramedian hinge median bar underactuated -->
  <joint name="finger_1_joint_paramedian_hinge_median_bar_underactuated" type="revolute">
    <parent link="finger_1_link_paramedian_hinge"/>
    <child link="finger_1_link_median_bar_underactuated"/>
    <axis xyz="0 0 1"/>
    <!-- hand calc 90 deg + atan(0.01227/0.00329) -->
    <origin rpy="0 0 1.5708" xyz="0.01227 0.00329 0"/>
    <limit effort="100" lower="-3.1416" upper="3.1416" velocity="100"/>
  </joint>
  <gazebo reference="finger_1_joint_paramedian_hinge_median_bar_underactuated">
    <implicitSpringDamper>1</implicitSpringDamper>
  </gazebo>
  <!-- Joint 1 -->
  <joint name="finger_1_joint_1" type="revolute">
    <origin rpy="0 0 -2.0906" xyz="0 0 0"/>
    <axis xyz="0 0 1"/>
    <parent link="finger_1_link_0"/>
    <child link="finger_1_link_1"/>
    <dynamics damping="1" friction="0"/>
    <!-- Limits: [0deg.,70deg.] -->
    <limit effort="60" lower="0" upper="1.2217" velocity="-1"/>
  </joint>
  <gazebo reference="finger_1_joint_1">
    <implicitSpringDamper>1</implicitSpringDamper>
  </gazebo>
  <!-- Joint 2 -->
  <joint name="finger_1_joint_2" type="revolute">
    <parent link="finger_1_link_1"/>
    <child link="finger_1_link_2"/>
    <dynamics damping="1" friction="0"/>
    <axis xyz="0 0 1"/>
    <origin rpy="0 0 0" xyz="0 0.05715 0"/>
    <!-- Limits: [0deg.,90deg.] -->
    <limit effort="60" lower="0" upper="1.5708" velocity="-1"/>
  </joint>
  <gazebo reference="finger_1_joint_2">
    <implicitSpringDamper>1</implicitSpringDamper>
  </gazebo>
  <!-- Joint 3 -->
  <joint name="finger_1_joint_3" type="revolute">
    <parent link="finger_1_link_2"/>
    <child link="finger_1_link_3"/>
    <dynamics damping="1" friction="0"/>
    <axis xyz="0 0 1"/>
    <origin rpy="0 0 2.0906" xyz="0 0.039 0"/>
    <!-- Limits: [-38deg.,60deg.] -->
    <limit effort="60" lower="-0.6632" upper="1.0471" velocity="-1"/>
  </joint>
  <gazebo reference="finger_1_joint_3">
    <implicitSpringDamper>1</implicitSpringDamper>
  </gazebo>
  <!-- end of joint list -->
  <!-- coupling joints in sdf -->
  <gazebo>
    <joint name="finger_1_link_proximal_actuating_bar_median_actuating_hinge_couple" type="revolute">
      <parent>finger_1_link_median_actuating_hinge</parent>
      <child>finger_1_link_proximal_actuating_bar</child>
      <pose>0.05398 0 0 0 0 0</pose>
      <axis>
        <dynamics>
          <damping>0</damping>
          <friction>0</friction>
        </dynamics>
        <xyz>0 0 1</xyz>
        <!-- <use_parent_model_frame>false</use_parent_model_frame> -->
      </axis>
    </joint>
  </gazebo>
  <gazebo reference="finger_1_link_proximal_actuating_bar_median_actuating_hinge_couple">
    <implicitSpringDamper>1</implicitSpringDamper>
  </gazebo>
  <gazebo>
    <joint name="finger_1_link_median_bar_link_3_couple" type="revolute">
      <parent>finger_1_link_3</parent>
      <child>finger_1_link_median_bar</child>
      <pose>0.0381 0 0 0 0 0</pose>
      <axis>
        <dynamics>
          <damping>0</damping>
          <friction>0</friction>
        </dynamics>
        <xyz>0 0 1</xyz>
        <!-- <use_parent_model_frame>false</use_parent_model_frame> -->
      </axis>
    </joint>
  </gazebo>
  <gazebo reference="finger_1_link_median_bar_link_3_couple">
    <implicitSpringDamper>1</implicitSpringDamper>
  </gazebo>
  <gazebo>
    <joint name="finger_1_link_paramedian_bar_paradistal_hinge_couple" type="revolute">
      <parent>finger_1_link_paradistal_hinge</parent>
      <child>finger_1_link_median_bar_underactuated</child>
      <pose>0.0381 0 0 0 0 0</pose>
      <axis>
        <dynamics>
          <damping>0</damping>
          <friction>0</friction>
        </dynamics>
        <xyz>0 0 1</xyz>
        <!-- <use_parent_model_frame>false</use_parent_model_frame> -->
      </axis>
    </joint>
  </gazebo>
  <gazebo reference="finger_1_link_median_bar_link_3_couple">
    <implicitSpringDamper>1</implicitSpringDamper>
  </gazebo>
  <gazebo>
    <joint name="finger_1_link_paradistal_hinge_link_3_couple" type="revolute">
      <parent>finger_1_link_paradistal_hinge</parent>
      <child>finger_1_link_3</child>
      <pose>0.0381 0 0 0 0 0</pose>
      <axis>
        <dynamics>
          <damping>0</damping>
          <friction>0</friction>
        </dynamics>
        <xyz>0 0 1</xyz>
        <!-- <use_parent_model_frame>false</use_parent_model_frame> -->
      </axis>
    </joint>
  </gazebo>
  <gazebo reference="finger_1_link_paradistal_hinge_link_3_couple">
    <implicitSpringDamper>1</implicitSpringDamper>
  </gazebo>
  <gazebo>
    <joint name="finger_1_link_paraproximal_bar_paramedian_hinge_couple" type="revolute">
      <parent>finger_1_link_paramedian_hinge</parent>
      <child>finger_1_link_paraproximal_bar</child>
      <pose>0.05770 0 0 0 0 0</pose>
      <axis>
        <dynamics>
          <damping>0</damping>
          <friction>0</friction>
        </dynamics>
        <xyz>0 0 1</xyz>
        <!-- <use_parent_model_frame>false</use_parent_model_frame> -->
      </axis>
    </joint>
  </gazebo>
  <gazebo reference="finger_1_link_paraproximal_bar_paramedian_hinge_couple">
    <implicitSpringDamper>1</implicitSpringDamper>
  </gazebo>
  <!-- Link list -->
  <!-- Link 0 -->
  <link name="finger_2_link_0">
    <visual>
      <origin rpy="0 0 0" xyz="0 0 0"/>
      <geometry>
        <mesh filename="package://robotiq_s_model_visualization/meshes/s-model_articulated/visual/link_0.STL"/>
      </geometry>
      <material name="green">
        <color rgba="0 1 0 1"/>
      </material>
    </visual>
    <collision>
      <origin rpy="0 0 0" xyz="0 0 0"/>
      <geometry>
        <mesh filename="package://robotiq_s_model_visualization/meshes/s-model_articulated/collision/link_0.STL"/>
      </geometry>
      <material name="yellow">
        <color rgba="0 1 1 1"/>
      </material>
    </collision>
    <inertial>
      <mass value="0.1"/>
      <origin xyz="-0.01 0 0"/>
      <inertia ixx="0.000018" ixy="0" ixz="0" iyy="0.000025" iyz="0" izz="0.000025"/>
    </inertial>
  </link>
  <gazebo reference="finger_2_link_0">
    <mu1>1.1</mu1>
    <mu2>1.1</mu2>
  </gazebo>
  <!-- Link 1 -->
  <link name="finger_2_link_1">
    <visual>
      <origin rpy="0 0 1.5708" xyz="0 0.05717 0"/>
      <geometry>
        <mesh filename="package://robotiq_s_model_visualization/meshes/s-model_articulated/visual/link_1.STL"/>
      </geometry>
      <material name="green"/>
    </visual>
    <collision>
      <origin rpy="0 0 1.5708" xyz="0 0.05717 0"/>
      <geometry>
        <mesh filename="package://robotiq_s_model_visualization/meshes/s-model_articulated/collision/link_1.STL"/>
      </geometry>
      <material name="yellow">
        <color rgba="0 1 1 1"/>
      </material>
    </collision>
    <inertial>
      <origin rpy="0 0 1.5708" xyz="0.00053 0.03218 0"/>
      <mass value="0.047"/>
      <inertia ixx="0.00000499332" ixy="0.00000091312" ixz="-0.00000000120" iyy="0.00006434531" iyz="-0.00000000007" izz="0.00006061917"/>
    </inertial>
  </link>
  <gazebo reference="finger_2_link_1">
    <mu1>1.1</mu1>
    <mu2>1.1</mu2>
  </gazebo>
  <!-- Link 2 -->
  <link name="finger_2_link_2">
    <visual>
      <origin rpy="0 0 1.5708" xyz="0 0.03810 0.0075"/>
      <geometry>
        <mesh filename="package://robotiq_s_model_visualization/meshes/s-model_articulated/visual/link_2.STL"/>
      </geometry>
      <material name="green"/>
    </visual>
    <collision>
      <origin rpy="0 0 1.5708" xyz="0 0.03810 0.0075"/>
      <geometry>
        <mesh filename="package://robotiq_s_model_visualization/meshes/s-model_articulated/collision/link_2.STL"/>
      </geometry>
      <material name="yellow"/>
    </collision>
    <inertial>
      <origin rpy="0 0 1.5708" xyz="0.00048 0.02167 0.00018"/>
      <mass value="0.03284"/>
      <inertia ixx="0.00000348008" ixy="0.00000031940" ixz="0.00000013041" iyy="0.00002248123" iyz="0.00000000291" izz="0.00001986346"/>
    </inertial>
  </link>
  <gazebo reference="finger_2_link_2">
    <mu1>1.1</mu1>
    <mu2>1.1</mu2>
  </gazebo>
  <!-- Link 3 -->
  <link name="finger_2_link_3">
    <visual>
      <origin rpy="0 0 0" xyz="0 0 0"/>
      <geometry>
        <mesh filename="package://robotiq_s_model_visualization/meshes/s-model_articulated/visual/link_3.STL"/>
      </geometry>
      <material name="green"/>
    </visual>
    <collision>
      <origin rpy="0 0 0" xyz="0 0 0"/>
      <geometry>
        <mesh filename="package://robotiq_s_model_visualization/meshes/s-model_articulated/collision/link_3.STL"/>
      </geometry>
      <material name="yellow"/>
    </collision>
    <inertial>
      <origin rpy="0 0 0" xyz="0.01626 0.00049 0.0002"/>
      <mass value="0.03354"/>
      <inertia ixx="0.00000305151" ixy="0.00000089792" ixz="0.00000000249" iyy="0.00001427978" iyz="-0.00000001191" izz="0.00001264126"/>
    </inertial>
  </link>
  <gazebo reference="finger_2_link_3">
    <mu1>1.1</mu1>
    <mu2>1.1</mu2>
  </gazebo>
  <!-- Link proximal actuating hinge -->
  <link name="finger_2_link_proximal_actuating_hinge">
    <visual>
      <origin rpy="0 0 0" xyz="0.01429 0 0"/>
      <geometry>
        <box size="0.02858 .0075 .002"/>
      </geometry>
    </visual>
    <collision>
      <origin rpy="0 0 0" xyz="0.01429 0 0"/>
      <geometry>
        <box size="0.02858 .0075 .002"/>
      </geometry>
    </collision>
    <inertial>
      <origin rpy="0 0 0" xyz="0.0012 -0.00162 -0.00161"/>
      <mass value="0.02647"/>
      <inertia ixx="0.00000156447" ixy="0.000000236226" ixz="-0.00000014862" iyy="0.00000221068" iyz="-0.00000014369" izz="0.00000323175"/>
    </inertial>
  </link>
  <gazebo reference="finger_2_link_proximal_actuating_hinge">
    <mu1>1.1</mu1>
    <mu2>1.1</mu2>
  </gazebo>
  <!-- Link paraproximal actuating hinge -->
  <link name="finger_2_link_paraproximal_actuating_hinge">
    <visual>
      <origin rpy="0 0 0" xyz="0.01143 0 0"/>
      <geometry>
        <box size="0.02286 .0075 .002"/>
      </geometry>
    </visual>
    <collision>
      <origin rpy="0 0 0" xyz="0.01143 0 0"/>
      <geometry>
        <box size="0.02286 .0075 .002"/>
      </geometry>
    </collision>
    <inertial>
      <origin rpy="0 0 0" xyz="0.0064 0 0"/>
      <!-- copied from proximal_actuating_hinge -->
      <mass value="0.00362"/>
      <inertia ixx="0.00000012043" ixy="0" ixz="0" iyy="0.00000053588" iyz="0" izz="0.00000065322"/>
    </inertial>
  </link>
  <gazebo reference="finger_2_link_paraproximal_actuating_hinge">
    <mu1>1.1</mu1>
    <mu2>1.1</mu2>
  </gazebo>
  <!-- Link proximal actuating bar -->
  <link name="finger_2_link_proximal_actuating_bar">
    <visual>
      <origin rpy="0 0 0" xyz="0.026789 0 0"/>
      <geometry>
        <box size="0.05398 .0075 .002"/>
      </geometry>
    </visual>
    <collision>
      <origin rpy="0 0 0" xyz="0.026789 0 0"/>
      <geometry>
        <box size="0.05398 .0075 .002"/>
      </geometry>
    </collision>
    <inertial>
      <origin rpy="0 0 0" xyz="0.02699 -0.00122 0"/>
      <mass value="0.00659"/>
      <inertia ixx="0.00000008348" ixy="-0.0000002179" ixz="0.00000000134" iyy="0.00000719076" iyz="0" izz="0.00000718272"/>
    </inertial>
  </link>
  <gazebo reference="finger_2_link_proximal_actuating_bar">
    <mu1>1.1</mu1>
    <mu2>1.1</mu2>
  </gazebo>
  <!-- Link paraproximal bar -->
  <link name="finger_2_link_paraproximal_bar">
    <visual>
      <origin rpy="0 0 0" xyz="0.02885 0 0"/>
      <geometry>
        <box size="0.05770 .0075 .002"/>
      </geometry>
    </visual>
    <collision>
      <origin rpy="0 0 0" xyz="0.02885 0 0"/>
      <geometry>
        <box size="0.05770 .0075 .002"/>
      </geometry>
    </collision>
    <inertial>
      <origin rpy="0 0 0" xyz="0.02858 -0.00129 0"/>
      <mass value="0.00732"/>
      <inertia ixx="0.00000009065" ixy="-0.00000027047" ixz="0.00000000142" iyy="0.00000878034" iyz="0" izz="0.00000877558"/>
    </inertial>
  </link>
  <gazebo reference="finger_2_link_paraproximal_bar">
    <mu1>1.1</mu1>
    <mu2>1.1</mu2>
  </gazebo>
  <!-- Link median actuating hinge -->
  <link name="finger_2_link_median_actuating_hinge">
    <visual>
      <origin rpy="0 0 0" xyz="0 0 0"/>
      <geometry>
        <box size=".02 .02 .002"/>
      </geometry>
    </visual>
    <collision>
      <origin rpy="0 0 0" xyz="0 0 0"/>
      <geometry>
        <box size=".02 .02 .002"/>
      </geometry>
    </collision>
    <inertial>
      <origin rpy="0 0 0" xyz="0.0092 0.00514 0"/>
      <mass value="0.00359"/>
      <inertia ixx="0.00000024735" ixy="0.00000023619" ixz="0" iyy="0.00000047681" iyz="0" izz="0.00000071813"/>
    </inertial>
  </link>
  <gazebo reference="finger_2_link_median_actuating_hinge">
    <mu1>1.1</mu1>
    <mu2>1.1</mu2>
  </gazebo>
  <!-- Link median bar -->
  <link name="finger_2_link_median_bar">
    <visual>
      <origin rpy="0 0 0" xyz="0.01905 0 0"/>
      <geometry>
        <box size="0.0381 .0075 .002"/>
      </geometry>
    </visual>
    <collision>
      <origin rpy="0 0 0" xyz="0.01905 0 0"/>
      <geometry>
        <box size="0.0381 .0075 .002"/>
      </geometry>
    </collision>
    <inertial>
      <origin rpy="0 0 0" xyz="0.01905 -0.00107 0"/>
      <mass value="0.00538"/>
      <inertia ixx="0.00000006639" ixy="-0.00000010996" ixz="0.00000000094" iyy="0.00000305318" iyz="0" izz="0.00000304657"/>
    </inertial>
  </link>
  <gazebo reference="finger_2_link_median_bar">
    <mu1>1.1</mu1>
    <mu2>1.1</mu2>
  </gazebo>
  <!-- Link paramedian hinge -->
  <link name="finger_2_link_paramedian_hinge">
    <visual>
      <origin rpy="0 0 0" xyz="0 0 0"/>
      <geometry>
        <box size=".02 .02 .002"/>
      </geometry>
    </visual>
    <collision>
      <origin rpy="0 0 0" xyz="0 0 0"/>
      <geometry>
        <box size=".02 .02 .002"/>
      </geometry>
    </collision>
    <inertial>
      <origin rpy="0 0 0" xyz="-0.01025 0.00046 0"/>
      <mass value="0.00276"/>
      <inertia ixx="0.00000004213" ixy="-0.00000001491" ixz="0" iyy="0.00000050258" iyz="0" izz="0.00000054007"/>
    </inertial>
  </link>
  <gazebo reference="finger_2_link_paramedian_hinge">
    <mu1>1.1</mu1>
    <mu2>1.1</mu2>
  </gazebo>
  <!-- Link median bar underactuated -->
  <link name="finger_2_link_median_bar_underactuated">
    <visual>
      <origin rpy="0 0 0" xyz="0.01905 0 0"/>
      <geometry>
        <box size="0.0381 .0075 .002"/>
      </geometry>
    </visual>
    <collision>
      <origin rpy="0 0 0" xyz="0.01905 0 0"/>
      <geometry>
        <box size="0.0381 .0075 .002"/>
      </geometry>
    </collision>
    <inertial>
      <origin rpy="0 0 0" xyz="0.01905 -0.00107 0"/>
      <mass value="0.00538"/>
      <inertia ixx="0.00000006639" ixy="-0.00000010996" ixz="-0.00000000094" iyy="0.00000305318" iyz="0" izz="0.00000304657"/>
    </inertial>
  </link>
  <gazebo reference="finger_2_link_median_bar_underactuated">
    <mu1>1.1</mu1>
    <mu2>1.1</mu2>
  </gazebo>
  <!-- Link paradistal hinge -->
  <link name="finger_2_link_paradistal_hinge">
    <visual>
      <origin rpy="0 0 0" xyz="0 0 0"/>
      <geometry>
        <box size=".02 .02 .002"/>
      </geometry>
    </visual>
    <collision>
      <origin rpy="0 0 0" xyz="0 0 0"/>
      <geometry>
        <box size=".02 0.02 .002"/>
      </geometry>
    </collision>
    <inertial>
      <origin rpy="0 0 0" xyz="0.00548 0 0"/>
      <mass value="0.00158"/>
      <inertia ixx="0.00000001907" ixy="0" ixz="0" iyy="0.00000010970" iyz="0" izz="0.00000012610"/>
    </inertial>
  </link>
  <gazebo reference="finger_2_link_paradistal_hinge">
    <mu1>1.1</mu1>
    <mu2>1.1</mu2>
  </gazebo>
  <!-- End of link list -->
  <!-- Joint list -->
  <!-- Joint proximal actuating hinge -->
  <joint name="finger_2_joint_proximal_actuating_hinge" type="revolute">
    <parent link="finger_2_link_0"/>
    <child link="finger_2_link_proximal_actuating_hinge"/>
    <axis xyz="0 0 1"/>
    <origin rpy="0 0 -2.0906" xyz="0 0 0.01"/>
    <limit effort="100" lower="-3.1416" upper="3.1416" velocity="100"/>
  </joint>
  <gazebo reference="finger_2_joint_proximal_actuating_hinge">
    <implicitSpringDamper>1</implicitSpringDamper>
  </gazebo>
  <!-- Joint paraproximal actuating hinge -->
  <joint name="finger_2_joint_paraproximal_actuating_hinge" type="revolute">
    <parent link="finger_2_link_0"/>
    <child link="finger_2_link_paraproximal_actuating_hinge"/>
    <axis xyz="0 0 1"/>
    <origin rpy="0 0 -2.0906" xyz="0 0 -0.01"/>
    <limit effort="100" lower="-3.1416" upper="3.1416" velocity="100"/>
  </joint>
  <gazebo reference="finger_2_joint_paraproximal_actuating_hinge">
    <implicitSpringDamper>1</implicitSpringDamper>
  </gazebo>
  <!-- Joint proximal actuating bar -->
  <joint name="finger_2_joint_proximal_actuating_bar" type="revolute">
    <parent link="finger_2_link_proximal_actuating_hinge"/>
    <child link="finger_2_link_proximal_actuating_bar"/>
    <axis xyz="0 0 1"/>
    <origin rpy="0 0 1.8616" xyz="0.02858 0 0"/>
    <limit effort="100" lower="-3.1416" upper="3.1416" velocity="100"/>
  </joint>
  <gazebo reference="finger_2_joint_proximal_actuating_bar">
    <implicitSpringDamper>1</implicitSpringDamper>
  </gazebo>
  <!-- Joint paraproximal bar -->
  <joint name="finger_2_joint_paraproximal_bar" type="revolute">
    <parent link="finger_2_link_paraproximal_actuating_hinge"/>
    <child link="finger_2_link_paraproximal_bar"/>
    <axis xyz="0 0 1"/>
    <origin rpy="0 0 1.57" xyz="0.02286 0 0"/>
    <limit effort="100" lower="-3.1416" upper="3.1416" velocity="100"/>
  </joint>
  <gazebo reference="finger_2_joint_paraproximal_bar">
    <implicitSpringDamper>1</implicitSpringDamper>
  </gazebo>
  <!-- Joint median actuating hinge -->
  <joint name="finger_2_joint_median_actuating_hinge" type="revolute">
    <parent link="finger_2_link_1"/>
    <child link="finger_2_link_median_actuating_hinge"/>
    <axis xyz="0 0 1"/>
    <origin rpy="0 0 -0.37" xyz="0 0.05715 0.01"/>
    <limit effort="100" lower="-3.1416" upper="3.1416" velocity="100"/>
  </joint>
  <gazebo reference="finger_2_joint_median_actuating_hinge">
    <implicitSpringDamper>1</implicitSpringDamper>
  </gazebo>
  <!-- Joint paramedian hinge -->
  <joint name="finger_2_joint_paramedian_hinge" type="revolute">
    <parent link="finger_2_link_1"/>
    <child link="finger_2_link_paramedian_hinge"/>
    <axis xyz="0 0 1"/>
    <!-- -0.37 is hand picked, 0.9719 is hand calculated from atan(0.02381/0.01625) -->
    <origin rpy="0 0 0" xyz="0 0.05715 -0.01"/>
    <limit effort="100" lower="-3.1416" upper="3.1416" velocity="100"/>
  </joint>
  <gazebo reference="finger_2_joint_paramedian_hinge">
    <implicitSpringDamper>1</implicitSpringDamper>
  </gazebo>
  <!-- Joint median actuating hinge median bar -->
  <joint name="finger_2_joint_median_actuating_hinge_median_bar" type="revolute">
    <parent link="finger_2_link_median_actuating_hinge"/>
    <child link="finger_2_link_median_bar"/>
    <axis xyz="0 0 1"/>
    <!-- hand calc 90 deg + atan(0.01516/0.01625) -->
    <origin rpy="0 0 2.3215" xyz="0.01625 0.01516 0"/>
    <limit effort="100" lower="-3.1416" upper="3.1416" velocity="100"/>
  </joint>
  <gazebo reference="finger_2_joint_median_actuating_hinge_median_bar">
    <implicitSpringDamper>1</implicitSpringDamper>
  </gazebo>
  <!-- Joint paradistal hinge -->
  <joint name="finger_2_joint_paradistal_hinge" type="revolute">
    <parent link="finger_2_link_2"/>
    <child link="finger_2_link_paradistal_hinge"/>
    <axis xyz="0 0 1"/>
    <origin rpy="0 0 0" xyz="0 0.039 -0.01"/>
    <limit effort="100" lower="-3.1416" upper="3.1416" velocity="100"/>
  </joint>
  <gazebo reference="finger_2_joint_paradistal_hinge">
    <implicitSpringDamper>1</implicitSpringDamper>
  </gazebo>
  <!-- Joint paramedian hinge median bar underactuated -->
  <joint name="finger_2_joint_paramedian_hinge_median_bar_underactuated" type="revolute">
    <parent link="finger_2_link_paramedian_hinge"/>
    <child link="finger_2_link_median_bar_underactuated"/>
    <axis xyz="0 0 1"/>
    <!-- hand calc 90 deg + atan(0.01227/0.00329) -->
    <origin rpy="0 0 1.5708" xyz="0.01227 0.00329 0"/>
    <limit effort="100" lower="-3.1416" upper="3.1416" velocity="100"/>
  </joint>
  <gazebo reference="finger_2_joint_paramedian_hinge_median_bar_underactuated">
    <implicitSpringDamper>1</implicitSpringDamper>
  </gazebo>
  <!-- Joint 1 -->
  <joint name="finger_2_joint_1" type="revolute">
    <origin rpy="0 0 -2.0906" xyz="0 0 0"/>
    <axis xyz="0 0 1"/>
    <parent link="finger_2_link_0"/>
    <child link="finger_2_link_1"/>
    <dynamics damping="1" friction="0"/>
    <!-- Limits: [0deg.,70deg.] -->
    <limit effort="60" lower="0" upper="1.2217" velocity="-1"/>
  </joint>
  <gazebo reference="finger_2_joint_1">
    <implicitSpringDamper>1</implicitSpringDamper>
  </gazebo>
  <!-- Joint 2 -->
  <joint name="finger_2_joint_2" type="revolute">
    <parent link="finger_2_link_1"/>
    <child link="finger_2_link_2"/>
    <dynamics damping="1" friction="0"/>
    <axis xyz="0 0 1"/>
    <origin rpy="0 0 0" xyz="0 0.05715 0"/>
    <!-- Limits: [0deg.,90deg.] -->
    <limit effort="60" lower="0" upper="1.5708" velocity="-1"/>
  </joint>
  <gazebo reference="finger_2_joint_2">
    <implicitSpringDamper>1</implicitSpringDamper>
  </gazebo>
  <!-- Joint 3 -->
  <joint name="finger_2_joint_3" type="revolute">
    <parent link="finger_2_link_2"/>
    <child link="finger_2_link_3"/>
    <dynamics damping="1" friction="0"/>
    <axis xyz="0 0 1"/>
    <origin rpy="0 0 2.0906" xyz="0 0.039 0"/>
    <!-- Limits: [-38deg.,60deg.] -->
    <limit effort="60" lower="-0.6632" upper="1.0471" velocity="-1"/>
  </joint>
  <gazebo reference="finger_2_joint_3">
    <implicitSpringDamper>1</implicitSpringDamper>
  </gazebo>
  <!-- end of joint list -->
  <!-- coupling joints in sdf -->
  <gazebo>
    <joint name="finger_2_link_proximal_actuating_bar_median_actuating_hinge_couple" type="revolute">
      <parent>finger_2_link_median_actuating_hinge</parent>
      <child>finger_2_link_proximal_actuating_bar</child>
      <pose>0.05398 0 0 0 0 0</pose>
      <axis>
        <dynamics>
          <damping>0</damping>
          <friction>0</friction>
        </dynamics>
        <xyz>0 0 1</xyz>
        <!-- <use_parent_model_frame>false</use_parent_model_frame> -->
      </axis>
    </joint>
  </gazebo>
  <gazebo reference="finger_2_link_proximal_actuating_bar_median_actuating_hinge_couple">
    <implicitSpringDamper>1</implicitSpringDamper>
  </gazebo>
  <gazebo>
    <joint name="finger_2_link_median_bar_link_3_couple" type="revolute">
      <parent>finger_2_link_3</parent>
      <child>finger_2_link_median_bar</child>
      <pose>0.0381 0 0 0 0 0</pose>
      <axis>
        <dynamics>
          <damping>0</damping>
          <friction>0</friction>
        </dynamics>
        <xyz>0 0 1</xyz>
        <!-- <use_parent_model_frame>false</use_parent_model_frame> -->
      </axis>
    </joint>
  </gazebo>
  <gazebo reference="finger_2_link_median_bar_link_3_couple">
    <implicitSpringDamper>1</implicitSpringDamper>
  </gazebo>
  <gazebo>
    <joint name="finger_2_link_paramedian_bar_paradistal_hinge_couple" type="revolute">
      <parent>finger_2_link_paradistal_hinge</parent>
      <child>finger_2_link_median_bar_underactuated</child>
      <pose>0.0381 0 0 0 0 0</pose>
      <axis>
        <dynamics>
          <damping>0</damping>
          <friction>0</friction>
        </dynamics>
        <xyz>0 0 1</xyz>
        <!-- <use_parent_model_frame>false</use_parent_model_frame> -->
      </axis>
    </joint>
  </gazebo>
  <gazebo reference="finger_2_link_median_bar_link_3_couple">
    <implicitSpringDamper>1</implicitSpringDamper>
  </gazebo>
  <gazebo>
    <joint name="finger_2_link_paradistal_hinge_link_3_couple" type="revolute">
      <parent>finger_2_link_paradistal_hinge</parent>
      <child>finger_2_link_3</child>
      <pose>0.0381 0 0 0 0 0</pose>
      <axis>
        <dynamics>
          <damping>0</damping>
          <friction>0</friction>
        </dynamics>
        <xyz>0 0 1</xyz>
        <!-- <use_parent_model_frame>false</use_parent_model_frame> -->
      </axis>
    </joint>
  </gazebo>
  <gazebo reference="finger_2_link_paradistal_hinge_link_3_couple">
    <implicitSpringDamper>1</implicitSpringDamper>
  </gazebo>
  <gazebo>
    <joint name="finger_2_link_paraproximal_bar_paramedian_hinge_couple" type="revolute">
      <parent>finger_2_link_paramedian_hinge</parent>
      <child>finger_2_link_paraproximal_bar</child>
      <pose>0.05770 0 0 0 0 0</pose>
      <axis>
        <dynamics>
          <damping>0</damping>
          <friction>0</friction>
        </dynamics>
        <xyz>0 0 1</xyz>
        <!-- <use_parent_model_frame>false</use_parent_model_frame> -->
      </axis>
    </joint>
  </gazebo>
  <gazebo reference="finger_2_link_paraproximal_bar_paramedian_hinge_couple">
    <implicitSpringDamper>1</implicitSpringDamper>
  </gazebo>
  <!-- Link list -->
  <!-- Link 0 -->
  <link name="finger_middle_link_0">
    <visual>
      <origin rpy="0 0 0" xyz="0 0 0"/>
      <geometry>
        <mesh filename="package://robotiq_s_model_visualization/meshes/s-model_articulated/visual/link_0.STL"/>
      </geometry>
      <material name="green">
        <color rgba="0 1 0 1"/>
      </material>
    </visual>
    <collision>
      <origin rpy="0 0 0" xyz="0 0 0"/>
      <geometry>
        <mesh filename="package://robotiq_s_model_visualization/meshes/s-model_articulated/collision/link_0.STL"/>
      </geometry>
      <material name="yellow">
        <color rgba="0 1 1 1"/>
      </material>
    </collision>
    <inertial>
      <mass value="0.1"/>
      <origin xyz="-0.01 0 0"/>
      <inertia ixx="0.000018" ixy="0" ixz="0" iyy="0.000025" iyz="0" izz="0.000025"/>
    </inertial>
  </link>
  <gazebo reference="finger_middle_link_0">
    <mu1>1.1</mu1>
    <mu2>1.1</mu2>
  </gazebo>
  <!-- Link 1 -->
  <link name="finger_middle_link_1">
    <visual>
      <origin rpy="0 0 1.5708" xyz="0 0.05717 0"/>
      <geometry>
        <mesh filename="package://robotiq_s_model_visualization/meshes/s-model_articulated/visual/link_1.STL"/>
      </geometry>
      <material name="green"/>
    </visual>
    <collision>
      <origin rpy="0 0 1.5708" xyz="0 0.05717 0"/>
      <geometry>
        <mesh filename="package://robotiq_s_model_visualization/meshes/s-model_articulated/collision/link_1.STL"/>
      </geometry>
      <material name="yellow">
        <color rgba="0 1 1 1"/>
      </material>
    </collision>
    <inertial>
      <origin rpy="0 0 1.5708" xyz="0.00053 0.03218 0"/>
      <mass value="0.047"/>
      <inertia ixx="0.00000499332" ixy="0.00000091312" ixz="-0.00000000120" iyy="0.00006434531" iyz="-0.00000000007" izz="0.00006061917"/>
    </inertial>
  </link>
  <gazebo reference="finger_middle_link_1">
    <mu1>1.1</mu1>
    <mu2>1.1</mu2>
  </gazebo>
  <!-- Link 2 -->
  <link name="finger_middle_link_2">
    <visual>
      <origin rpy="0 0 1.5708" xyz="0 0.03810 0.0075"/>
      <geometry>
        <mesh filename="package://robotiq_s_model_visualization/meshes/s-model_articulated/visual/link_2.STL"/>
      </geometry>
      <material name="green"/>
    </visual>
    <collision>
      <origin rpy="0 0 1.5708" xyz="0 0.03810 0.0075"/>
      <geometry>
        <mesh filename="package://robotiq_s_model_visualization/meshes/s-model_articulated/collision/link_2.STL"/>
      </geometry>
      <material name="yellow"/>
    </collision>
    <inertial>
      <origin rpy="0 0 1.5708" xyz="0.00048 0.02167 0.00018"/>
      <mass value="0.03284"/>
      <inertia ixx="0.00000348008" ixy="0.00000031940" ixz="0.00000013041" iyy="0.00002248123" iyz="0.00000000291" izz="0.00001986346"/>
    </inertial>
  </link>
  <gazebo reference="finger_middle_link_2">
    <mu1>1.1</mu1>
    <mu2>1.1</mu2>
  </gazebo>
  <!-- Link 3 -->
  <link name="finger_middle_link_3">
    <visual>
      <origin rpy="0 0 0" xyz="0 0 0"/>
      <geometry>
        <mesh filename="package://robotiq_s_model_visualization/meshes/s-model_articulated/visual/link_3.STL"/>
      </geometry>
      <material name="green"/>
    </visual>
    <collision>
      <origin rpy="0 0 0" xyz="0 0 0"/>
      <geometry>
        <mesh filename="package://robotiq_s_model_visualization/meshes/s-model_articulated/collision/link_3.STL"/>
      </geometry>
      <material name="yellow"/>
    </collision>
    <inertial>
      <origin rpy="0 0 0" xyz="0.01626 0.00049 0.0002"/>
      <mass value="0.03354"/>
      <inertia ixx="0.00000305151" ixy="0.00000089792" ixz="0.00000000249" iyy="0.00001427978" iyz="-0.00000001191" izz="0.00001264126"/>
    </inertial>
  </link>
  <gazebo reference="finger_middle_link_3">
    <mu1>1.1</mu1>
    <mu2>1.1</mu2>
  </gazebo>
  <!-- Link proximal actuating hinge -->
  <link name="finger_middle_link_proximal_actuating_hinge">
    <visual>
      <origin rpy="0 0 0" xyz="0.01429 0 0"/>
      <geometry>
        <box size="0.02858 .0075 .002"/>
      </geometry>
    </visual>
    <collision>
      <origin rpy="0 0 0" xyz="0.01429 0 0"/>
      <geometry>
        <box size="0.02858 .0075 .002"/>
      </geometry>
    </collision>
    <inertial>
      <origin rpy="0 0 0" xyz="0.0012 -0.00162 -0.00161"/>
      <mass value="0.02647"/>
      <inertia ixx="0.00000156447" ixy="0.000000236226" ixz="-0.00000014862" iyy="0.00000221068" iyz="-0.00000014369" izz="0.00000323175"/>
    </inertial>
  </link>
  <gazebo reference="finger_middle_link_proximal_actuating_hinge">
    <mu1>1.1</mu1>
    <mu2>1.1</mu2>
  </gazebo>
  <!-- Link paraproximal actuating hinge -->
  <link name="finger_middle_link_paraproximal_actuating_hinge">
    <visual>
      <origin rpy="0 0 0" xyz="0.01143 0 0"/>
      <geometry>
        <box size="0.02286 .0075 .002"/>
      </geometry>
    </visual>
    <collision>
      <origin rpy="0 0 0" xyz="0.01143 0 0"/>
      <geometry>
        <box size="0.02286 .0075 .002"/>
      </geometry>
    </collision>
    <inertial>
      <origin rpy="0 0 0" xyz="0.0064 0 0"/>
      <!-- copied from proximal_actuating_hinge -->
      <mass value="0.00362"/>
      <inertia ixx="0.00000012043" ixy="0" ixz="0" iyy="0.00000053588" iyz="0" izz="0.00000065322"/>
    </inertial>
  </link>
  <gazebo reference="finger_middle_link_paraproximal_actuating_hinge">
    <mu1>1.1</mu1>
    <mu2>1.1</mu2>
  </gazebo>
  <!-- Link proximal actuating bar -->
  <link name="finger_middle_link_proximal_actuating_bar">
    <visual>
      <origin rpy="0 0 0" xyz="0.026789 0 0"/>
      <geometry>
        <box size="0.05398 .0075 .002"/>
      </geometry>
    </visual>
    <collision>
      <origin rpy="0 0 0" xyz="0.026789 0 0"/>
      <geometry>
        <box size="0.05398 .0075 .002"/>
      </geometry>
    </collision>
    <inertial>
      <origin rpy="0 0 0" xyz="0.02699 -0.00122 0"/>
      <mass value="0.00659"/>
      <inertia ixx="0.00000008348" ixy="-0.0000002179" ixz="0.00000000134" iyy="0.00000719076" iyz="0" izz="0.00000718272"/>
    </inertial>
  </link>
  <gazebo reference="finger_middle_link_proximal_actuating_bar">
    <mu1>1.1</mu1>
    <mu2>1.1</mu2>
  </gazebo>
  <!-- Link paraproximal bar -->
  <link name="finger_middle_link_paraproximal_bar">
    <visual>
      <origin rpy="0 0 0" xyz="0.02885 0 0"/>
      <geometry>
        <box size="0.05770 .0075 .002"/>
      </geometry>
    </visual>
    <collision>
      <origin rpy="0 0 0" xyz="0.02885 0 0"/>
      <geometry>
        <box size="0.05770 .0075 .002"/>
      </geometry>
    </collision>
    <inertial>
      <origin rpy="0 0 0" xyz="0.02858 -0.00129 0"/>
      <mass value="0.00732"/>
      <inertia ixx="0.00000009065" ixy="-0.00000027047" ixz="0.00000000142" iyy="0.00000878034" iyz="0" izz="0.00000877558"/>
    </inertial>
  </link>
  <gazebo reference="finger_middle_link_paraproximal_bar">
    <mu1>1.1</mu1>
    <mu2>1.1</mu2>
  </gazebo>
  <!-- Link median actuating hinge -->
  <link name="finger_middle_link_median_actuating_hinge">
    <visual>
      <origin rpy="0 0 0" xyz="0 0 0"/>
      <geometry>
        <box size=".02 .02 .002"/>
      </geometry>
    </visual>
    <collision>
      <origin rpy="0 0 0" xyz="0 0 0"/>
      <geometry>
        <box size=".02 .02 .002"/>
      </geometry>
    </collision>
    <inertial>
      <origin rpy="0 0 0" xyz="0.0092 0.00514 0"/>
      <mass value="0.00359"/>
      <inertia ixx="0.00000024735" ixy="0.00000023619" ixz="0" iyy="0.00000047681" iyz="0" izz="0.00000071813"/>
    </inertial>
  </link>
  <gazebo reference="finger_middle_link_median_actuating_hinge">
    <mu1>1.1</mu1>
    <mu2>1.1</mu2>
  </gazebo>
  <!-- Link median bar -->
  <link name="finger_middle_link_median_bar">
    <visual>
      <origin rpy="0 0 0" xyz="0.01905 0 0"/>
      <geometry>
        <box size="0.0381 .0075 .002"/>
      </geometry>
    </visual>
    <collision>
      <origin rpy="0 0 0" xyz="0.01905 0 0"/>
      <geometry>
        <box size="0.0381 .0075 .002"/>
      </geometry>
    </collision>
    <inertial>
      <origin rpy="0 0 0" xyz="0.01905 -0.00107 0"/>
      <mass value="0.00538"/>
      <inertia ixx="0.00000006639" ixy="-0.00000010996" ixz="0.00000000094" iyy="0.00000305318" iyz="0" izz="0.00000304657"/>
    </inertial>
  </link>
  <gazebo reference="finger_middle_link_median_bar">
    <mu1>1.1</mu1>
    <mu2>1.1</mu2>
  </gazebo>
  <!-- Link paramedian hinge -->
  <link name="finger_middle_link_paramedian_hinge">
    <visual>
      <origin rpy="0 0 0" xyz="0 0 0"/>
      <geometry>
        <box size=".02 .02 .002"/>
      </geometry>
    </visual>
    <collision>
      <origin rpy="0 0 0" xyz="0 0 0"/>
      <geometry>
        <box size=".02 .02 .002"/>
      </geometry>
    </collision>
    <inertial>
      <origin rpy="0 0 0" xyz="-0.01025 0.00046 0"/>
      <mass value="0.00276"/>
      <inertia ixx="0.00000004213" ixy="-0.00000001491" ixz="0" iyy="0.00000050258" iyz="0" izz="0.00000054007"/>
    </inertial>
  </link>
  <gazebo reference="finger_middle_link_paramedian_hinge">
    <mu1>1.1</mu1>
    <mu2>1.1</mu2>
  </gazebo>
  <!-- Link median bar underactuated -->
  <link name="finger_middle_link_median_bar_underactuated">
    <visual>
      <origin rpy="0 0 0" xyz="0.01905 0 0"/>
      <geometry>
        <box size="0.0381 .0075 .002"/>
      </geometry>
    </visual>
    <collision>
      <origin rpy="0 0 0" xyz="0.01905 0 0"/>
      <geometry>
        <box size="0.0381 .0075 .002"/>
      </geometry>
    </collision>
    <inertial>
      <origin rpy="0 0 0" xyz="0.01905 -0.00107 0"/>
      <mass value="0.00538"/>
      <inertia ixx="0.00000006639" ixy="-0.00000010996" ixz="-0.00000000094" iyy="0.00000305318" iyz="0" izz="0.00000304657"/>
    </inertial>
  </link>
  <gazebo reference="finger_middle_link_median_bar_underactuated">
    <mu1>1.1</mu1>
    <mu2>1.1</mu2>
  </gazebo>
  <!-- Link paradistal hinge -->
  <link name="finger_middle_link_paradistal_hinge">
    <visual>
      <origin rpy="0 0 0" xyz="0 0 0"/>
      <geometry>
        <box size=".02 .02 .002"/>
      </geometry>
    </visual>
    <collision>
      <origin rpy="0 0 0" xyz="0 0 0"/>
      <geometry>
        <box size=".02 0.02 .002"/>
      </geometry>
    </collision>
    <inertial>
      <origin rpy="0 0 0" xyz="0.00548 0 0"/>
      <mass value="0.00158"/>
      <inertia ixx="0.00000001907" ixy="0" ixz="0" iyy="0.00000010970" iyz="0" izz="0.00000012610"/>
    </inertial>
  </link>
  <gazebo reference="finger_middle_link_paradistal_hinge">
    <mu1>1.1</mu1>
    <mu2>1.1</mu2>
  </gazebo>
  <!-- End of link list -->
  <!-- Joint list -->
  <!-- Joint proximal actuating hinge -->
  <joint name="finger_middle_joint_proximal_actuating_hinge" type="revolute">
    <parent link="finger_middle_link_0"/>
    <child link="finger_middle_link_proximal_actuating_hinge"/>
    <axis xyz="0 0 1"/>
    <origin rpy="0 0 -2.0906" xyz="0 0 0.01"/>
    <limit effort="100" lower="-3.1416" upper="3.1416" velocity="100"/>
  </joint>
  <gazebo reference="finger_middle_joint_proximal_actuating_hinge">
    <implicitSpringDamper>1</implicitSpringDamper>
  </gazebo>
  <!-- Joint paraproximal actuating hinge -->
  <joint name="finger_middle_joint_paraproximal_actuating_hinge" type="revolute">
    <parent link="finger_middle_link_0"/>
    <child link="finger_middle_link_paraproximal_actuating_hinge"/>
    <axis xyz="0 0 1"/>
    <origin rpy="0 0 -2.0906" xyz="0 0 -0.01"/>
    <limit effort="100" lower="-3.1416" upper="3.1416" velocity="100"/>
  </joint>
  <gazebo reference="finger_middle_joint_paraproximal_actuating_hinge">
    <implicitSpringDamper>1</implicitSpringDamper>
  </gazebo>
  <!-- Joint proximal actuating bar -->
  <joint name="finger_middle_joint_proximal_actuating_bar" type="revolute">
    <parent link="finger_middle_link_proximal_actuating_hinge"/>
    <child link="finger_middle_link_proximal_actuating_bar"/>
    <axis xyz="0 0 1"/>
    <origin rpy="0 0 1.8616" xyz="0.02858 0 0"/>
    <limit effort="100" lower="-3.1416" upper="3.1416" velocity="100"/>
  </joint>
  <gazebo reference="finger_middle_joint_proximal_actuating_bar">
    <implicitSpringDamper>1</implicitSpringDamper>
  </gazebo>
  <!-- Joint paraproximal bar -->
  <joint name="finger_middle_joint_paraproximal_bar" type="revolute">
    <parent link="finger_middle_link_paraproximal_actuating_hinge"/>
    <child link="finger_middle_link_paraproximal_bar"/>
    <axis xyz="0 0 1"/>
    <origin rpy="0 0 1.57" xyz="0.02286 0 0"/>
    <limit effort="100" lower="-3.1416" upper="3.1416" velocity="100"/>
  </joint>
  <gazebo reference="finger_middle_joint_paraproximal_bar">
    <implicitSpringDamper>1</implicitSpringDamper>
  </gazebo>
  <!-- Joint median actuating hinge -->
  <joint name="finger_middle_joint_median_actuating_hinge" type="revolute">
    <parent link="finger_middle_link_1"/>
    <child link="finger_middle_link_median_actuating_hinge"/>
    <axis xyz="0 0 1"/>
    <origin rpy="0 0 -0.37" xyz="0 0.05715 0.01"/>
    <limit effort="100" lower="-3.1416" upper="3.1416" velocity="100"/>
  </joint>
  <gazebo reference="finger_middle_joint_median_actuating_hinge">
    <implicitSpringDamper>1</implicitSpringDamper>
  </gazebo>
  <!-- Joint paramedian hinge -->
  <joint name="finger_middle_joint_paramedian_hinge" type="revolute">
    <parent link="finger_middle_link_1"/>
    <child link="finger_middle_link_paramedian_hinge"/>
    <axis xyz="0 0 1"/>
    <!-- -0.37 is hand picked, 0.9719 is hand calculated from atan(0.02381/0.01625) -->
    <origin rpy="0 0 0" xyz="0 0.05715 -0.01"/>
    <limit effort="100" lower="-3.1416" upper="3.1416" velocity="100"/>
  </joint>
  <gazebo reference="finger_middle_joint_paramedian_hinge">
    <implicitSpringDamper>1</implicitSpringDamper>
  </gazebo>
  <!-- Joint median actuating hinge median bar -->
  <joint name="finger_middle_joint_median_actuating_hinge_median_bar" type="revolute">
    <parent link="finger_middle_link_median_actuating_hinge"/>
    <child link="finger_middle_link_median_bar"/>
    <axis xyz="0 0 1"/>
    <!-- hand calc 90 deg + atan(0.01516/0.01625) -->
    <origin rpy="0 0 2.3215" xyz="0.01625 0.01516 0"/>
    <limit effort="100" lower="-3.1416" upper="3.1416" velocity="100"/>
  </joint>
  <gazebo reference="finger_middle_joint_median_actuating_hinge_median_bar">
    <implicitSpringDamper>1</implicitSpringDamper>
  </gazebo>
  <!-- Joint paradistal hinge -->
  <joint name="finger_middle_joint_paradistal_hinge" type="revolute">
    <parent link="finger_middle_link_2"/>
    <child link="finger_middle_link_paradistal_hinge"/>
    <axis xyz="0 0 1"/>
    <origin rpy="0 0 0" xyz="0 0.039 -0.01"/>
    <limit effort="100" lower="-3.1416" upper="3.1416" velocity="100"/>
  </joint>
  <gazebo reference="finger_middle_joint_paradistal_hinge">
    <implicitSpringDamper>1</implicitSpringDamper>
  </gazebo>
  <!-- Joint paramedian hinge median bar underactuated -->
  <joint name="finger_middle_joint_paramedian_hinge_median_bar_underactuated" type="revolute">
    <parent link="finger_middle_link_paramedian_hinge"/>
    <child link="finger_middle_link_median_bar_underactuated"/>
    <axis xyz="0 0 1"/>
    <!-- hand calc 90 deg + atan(0.01227/0.00329) -->
    <origin rpy="0 0 1.5708" xyz="0.01227 0.00329 0"/>
    <limit effort="100" lower="-3.1416" upper="3.1416" velocity="100"/>
  </joint>
  <gazebo reference="finger_middle_joint_paramedian_hinge_median_bar_underactuated">
    <implicitSpringDamper>1</implicitSpringDamper>
  </gazebo>
  <!-- Joint 1 -->
  <joint name="finger_middle_joint_1" type="revolute">
    <origin rpy="0 0 -2.0906" xyz="0 0 0"/>
    <axis xyz="0 0 1"/>
    <parent link="finger_middle_link_0"/>
    <child link="finger_middle_link_1"/>
    <dynamics damping="1" friction="0"/>
    <!-- Limits: [0deg.,70deg.] -->
    <limit effort="60" lower="0" upper="1.2217" velocity="-1"/>
  </joint>
  <gazebo reference="finger_middle_joint_1">
    <implicitSpringDamper>1</implicitSpringDamper>
  </gazebo>
  <!-- Joint 2 -->
  <joint name="finger_middle_joint_2" type="revolute">
    <parent link="finger_middle_link_1"/>
    <child link="finger_middle_link_2"/>
    <dynamics damping="1" friction="0"/>
    <axis xyz="0 0 1"/>
    <origin rpy="0 0 0" xyz="0 0.05715 0"/>
    <!-- Limits: [0deg.,90deg.] -->
    <limit effort="60" lower="0" upper="1.5708" velocity="-1"/>
  </joint>
  <gazebo reference="finger_middle_joint_2">
    <implicitSpringDamper>1</implicitSpringDamper>
  </gazebo>
  <!-- Joint 3 -->
  <joint name="finger_middle_joint_3" type="revolute">
    <parent link="finger_middle_link_2"/>
    <child link="finger_middle_link_3"/>
    <dynamics damping="1" friction="0"/>
    <axis xyz="0 0 1"/>
    <origin rpy="0 0 2.0906" xyz="0 0.039 0"/>
    <!-- Limits: [-38deg.,60deg.] -->
    <limit effort="60" lower="-0.6632" upper="1.0471" velocity="-1"/>
  </joint>
  <gazebo reference="finger_middle_joint_3">
    <implicitSpringDamper>1</implicitSpringDamper>
  </gazebo>
  <!-- end of joint list -->
  <!-- coupling joints in sdf -->
  <gazebo>
    <joint name="finger_middle_link_proximal_actuating_bar_median_actuating_hinge_couple" type="revolute">
      <parent>finger_middle_link_median_actuating_hinge</parent>
      <child>finger_middle_link_proximal_actuating_bar</child>
      <pose>0.05398 0 0 0 0 0</pose>
      <axis>
        <dynamics>
          <damping>0</damping>
          <friction>0</friction>
        </dynamics>
        <xyz>0 0 1</xyz>
        <!-- <use_parent_model_frame>false</use_parent_model_frame> -->
      </axis>
    </joint>
  </gazebo>
  <gazebo reference="finger_middle_link_proximal_actuating_bar_median_actuating_hinge_couple">
    <implicitSpringDamper>1</implicitSpringDamper>
  </gazebo>
  <gazebo>
    <joint name="finger_middle_link_median_bar_link_3_couple" type="revolute">
      <parent>finger_middle_link_3</parent>
      <child>finger_middle_link_median_bar</child>
      <pose>0.0381 0 0 0 0 0</pose>
      <axis>
        <dynamics>
          <damping>0</damping>
          <friction>0</friction>
        </dynamics>
        <xyz>0 0 1</xyz>
        <!-- <use_parent_model_frame>false</use_parent_model_frame> -->
      </axis>
    </joint>
  </gazebo>
  <gazebo reference="finger_middle_link_median_bar_link_3_couple">
    <implicitSpringDamper>1</implicitSpringDamper>
  </gazebo>
  <gazebo>
    <joint name="finger_middle_link_paramedian_bar_paradistal_hinge_couple" type="revolute">
      <parent>finger_middle_link_paradistal_hinge</parent>
      <child>finger_middle_link_median_bar_underactuated</child>
      <pose>0.0381 0 0 0 0 0</pose>
      <axis>
        <dynamics>
          <damping>0</damping>
          <friction>0</friction>
        </dynamics>
        <xyz>0 0 1</xyz>
        <!-- <use_parent_model_frame>false</use_parent_model_frame> -->
      </axis>
    </joint>
  </gazebo>
  <gazebo reference="finger_middle_link_median_bar_link_3_couple">
    <implicitSpringDamper>1</implicitSpringDamper>
  </gazebo>
  <gazebo>
    <joint name="finger_middle_link_paradistal_hinge_link_3_couple" type="revolute">
      <parent>finger_middle_link_paradistal_hinge</parent>
      <child>finger_middle_link_3</child>
      <pose>0.0381 0 0 0 0 0</pose>
      <axis>
        <dynamics>
          <damping>0</damping>
          <friction>0</friction>
        </dynamics>
        <xyz>0 0 1</xyz>
        <!-- <use_parent_model_frame>false</use_parent_model_frame> -->
      </axis>
    </joint>
  </gazebo>
  <gazebo reference="finger_middle_link_paradistal_hinge_link_3_couple">
    <implicitSpringDamper>1</implicitSpringDamper>
  </gazebo>
  <gazebo>
    <joint name="finger_middle_link_paraproximal_bar_paramedian_hinge_couple" type="revolute">
      <parent>finger_middle_link_paramedian_hinge</parent>
      <child>finger_middle_link_paraproximal_bar</child>
      <pose>0.05770 0 0 0 0 0</pose>
      <axis>
        <dynamics>
          <damping>0</damping>
          <friction>0</friction>
        </dynamics>
        <xyz>0 0 1</xyz>
        <!-- <use_parent_model_frame>false</use_parent_model_frame> -->
      </axis>
    </joint>
  </gazebo>
  <gazebo reference="finger_middle_link_paraproximal_bar_paramedian_hinge_couple">
    <implicitSpringDamper>1</implicitSpringDamper>
  </gazebo>
  <!-- link list -->
  <!-- Link palm -->
  <link name="palm">
    <visual>
      <geometry>
        <mesh filename="package://robotiq_s_model_visualization/meshes/s-model_articulated/visual/palm.STL"/>
      </geometry>
      <material name="green">
        <color rgba="0 1 0 1"/>
      </material>
    </visual>
    <!-- Simple shape collision -->
    <collision>
      <origin rpy="0 0 0" xyz="0 0 0"/>
      <geometry>
        <box size="0.1 0.1 0.1"/>
      </geometry>
      <material name="yellow">
        <color rgba="0 1 1 1"/>
      </material>
    </collision>
    <inertial>
      <origin rpy="0 0 0" xyz="0 0 0"/>
      <mass value="1.3"/>
      <inertia ixx="0.0035" ixy="0" ixz="-0" iyy="0.0035" iyz="0" izz="0.0035"/>
    </inertial>
  </link>
  <gazebo reference="palm">
    <mu1>1.1</mu1>
    <mu2>1.1</mu2>
  </gazebo>
  <!-- End of link list -->
  <!-- Joint list -->
  <!-- Joint palm_finger_1_joint -->
  <joint name="palm_finger_1_joint" type="revolute">
    <parent link="palm"/>
    <child link="finger_1_link_0"/>
    <dynamics damping="1" friction="0"/>
    <axis xyz="0 1 0"/>
    <origin rpy="0 3.1416 -1.57" xyz="-0.0455 0.0214 0.036"/>
    <!-- Limits: [-17deg.,17deg.] -->
    <limit effort="60" lower="-0.2967" upper="0.2967" velocity="-1"/>
  </joint>
  <gazebo reference="palm_finger_1_joint">
    <implicitSpringDamper>1</implicitSpringDamper>
  </gazebo>
  <!-- Joint palm_finger_2_joint -->
  <joint name="palm_finger_2_joint" type="revolute">
    <parent link="palm"/>
    <child link="finger_2_link_0"/>
    <dynamics damping="1" friction="0"/>
    <axis xyz="0 1 0"/>
    <origin rpy="0 3.1416 -1.57" xyz="-0.0455 0.0214 -0.036"/>
    <!-- Limits: [-17deg.,17deg.] -->
    <limit effort="60" lower="-0.2967" upper="0.2967" velocity="-1"/>
  </joint>
  <gazebo reference="palm_finger_2_joint">
    <implicitSpringDamper>1</implicitSpringDamper>
  </gazebo>
  <!-- Joint palm_finger_middle_joint -->
  <joint name="palm_finger_middle_joint" type="revolute">
    <parent link="palm"/>
    <child link="finger_middle_link_0"/>
    <dynamics damping="1" friction="0"/>
    <axis xyz="0 1 0"/>
    <origin rpy="0 0 1.57" xyz="0.0455 0.0214 0"/>
    <limit effort="60" lower="0" upper="0" velocity="-1"/>
  </joint>
  <gazebo reference="palm_finger_middle_joint">
    <implicitSpringDamper>1</implicitSpringDamper>
  </gazebo>
  <!-- end of joint list -->

</robot>
