<?xml version="1.0" ?>
<!-- =================================================================================== -->
<!-- |    This document was autogenerated by xacro from ridgeback.urdf.xacro           | -->
<!-- |    EDITING THIS FILE BY HAND IS NOT RECOMMENDED                                 | -->
<!-- =================================================================================== -->
<robot name="thing" xmlns:xacro="http://ros.org/wiki/xacro">
  <material name="dark_grey">
    <color rgba="0.2 0.2 0.2 1.0"/>
  </material>
  <material name="light_grey">
    <color rgba="0.4 0.4 0.4 1.0"/>
  </material>
  <material name="red">
    <color rgba="0.8 0.0 0.0 1.0"/>
  </material>
  <material name="white">
    <color rgba="0.9 0.9 0.9 1.0"/>
  </material>
  <material name="yellow">
    <color rgba="0.8 0.8 0.0 1.0"/>
  </material>
  <material name="black">
    <color rgba="0.15 0.15 0.15 1.0"/>
  </material>

  <!-- Ridgeback wheels -->
  <link name="front_rocker_link">
    <visual>
      <origin rpy="1.57079632679 0 1.57079632679" xyz="0 0 0"/>
      <geometry>
        <mesh filename="assets/ridgeback_description/meshes/rocker.stl"/>
      </geometry>
      <material name="black"/>
    </visual>
    <inertial>
      <origin rpy="1.57079632679 0 1.57079632679" xyz="0 0 0"/>
      <mass value="10.267"/>
      <inertia ixx="0.0288" ixy="2.20484e-6" ixz="-1.3145e-5" iyy="0.4324" iyz="1.8944e-3" izz="0.4130"/>
    </inertial>
  </link>
  <joint name="front_rocker" type="fixed">
    <parent link="axle_link"/>
    <child link="front_rocker_link"/>
    <origin rpy="0 0 0" xyz="0.319 0 0"/>
    <axis xyz="1 0 0"/>
    <limit effort="0" lower="-0.08726" upper="0.08726" velocity="0"/>
  </joint>
  <link name="front_left_wheel_link">
    <contact>
      <lateral_friction value="1.0"/>
      <rolling_friction value="0.0"/>
      <stiffness value="30000"/>
      <damping value="10000"/>
    </contact>
    <inertial>
      <origin rpy="0 0 0" xyz="0 0 0"/>
      <mass value="2.637"/>
      <!--<inertia ixx="3.3212e-3" ixy="0" ixz="0" iyy="6.6424e-3" iyz="0" izz="3.3212e-3"/>-->
      <inertia ixx="0.02467" ixy="0" ixz="0" iyy="0.02467" iyz="0" izz="0.04411"/>
    </inertial>
    <visual>
      <origin rpy="1.57079632679 0 0" xyz="0 0 0"/>
      <geometry>
        <mesh filename="assets/ridgeback_description/meshes/wheel.stl"/>
      </geometry>
      <material name="black"/>
    </visual>
    <collision>
      <origin rpy="1.57079632679 0 0" xyz="0 0 0"/>
      <geometry>
        <cylinder length="0.079" radius="0.0759"/>
      </geometry>
    </collision>
  </link>
  <!-- <joint name="front_left_wheel" type="continuous"> -->
  <joint name="front_left_wheel" type="fixed">
    <parent link="front_rocker_link"/>
    <child link="front_left_wheel_link"/>
    <origin rpy="0 0 0" xyz="0 0.2755 0"/>
    <axis xyz="0 1 0"/>
  </joint>
  <link name="front_right_wheel_link">
    <contact>
      <lateral_friction value="1.0"/>
      <rolling_friction value="0.0"/>
      <stiffness value="30000"/>
      <damping value="10000"/>
    </contact>
    <inertial>
      <origin rpy="0 0 0" xyz="0 0 0"/>
      <mass value="2.637"/>
      <!--<inertia ixx="3.3212e-3" ixy="0" ixz="0" iyy="6.6424e-3" iyz="0" izz="3.3212e-3"/>-->
      <inertia ixx="0.02467" ixy="0" ixz="0" iyy="0.02467" iyz="0" izz="0.04411"/>
    </inertial>
    <visual>
      <origin rpy="1.57079632679 0 0" xyz="0 0 0"/>
      <geometry>
        <mesh filename="assets/ridgeback_description/meshes/wheel.stl"/>
      </geometry>
      <material name="black"/>
    </visual>
    <collision>
      <origin rpy="1.57079632679 0 0" xyz="0 0 0"/>
      <geometry>
        <cylinder length="0.079" radius="0.0759"/>
      </geometry>
    </collision>
  </link>
  <!-- <joint name="front_right_wheel" type="continuous"> -->
  <joint name="front_right_wheel" type="fixed">
    <parent link="front_rocker_link"/>
    <child link="front_right_wheel_link"/>
    <origin rpy="0 0 0" xyz="0 -0.2755 0"/>
    <axis xyz="0 1 0"/>
  </joint>
  <link name="rear_rocker_link">
    <visual>
      <origin rpy="1.57079632679 0 1.57079632679" xyz="0 0 0"/>
      <geometry>
        <mesh filename="assets/ridgeback_description/meshes/rocker.stl"/>
      </geometry>
      <material name="black"/>
    </visual>
    <inertial>
      <origin rpy="1.57079632679 0 1.57079632679" xyz="0 0 0"/>
      <mass value="10.267"/>
      <inertia ixx="0.0288" ixy="2.20484e-6" ixz="-1.3145e-5" iyy="0.4324" iyz="1.8944e-3" izz="0.4130"/>
    </inertial>
  </link>
  <joint name="rear_rocker" type="fixed">
    <parent link="axle_link"/>
    <child link="rear_rocker_link"/>
    <origin rpy="0 0 0" xyz="-0.319 0 0"/>
    <axis xyz="1 0 0"/>
    <limit effort="0" velocity="0"/>
  </joint>
  <link name="rear_left_wheel_link">
    <contact>
      <lateral_friction value="1.0"/>
      <rolling_friction value="0.0"/>
      <stiffness value="30000"/>
      <damping value="10000"/>
    </contact>
    <inertial>
      <origin rpy="0 0 0" xyz="0 0 0"/>
      <mass value="2.637"/>
      <!--<inertia ixx="3.3212e-3" ixy="0" ixz="0" iyy="6.6424e-3" iyz="0" izz="3.3212e-3"/>-->
      <inertia ixx="0.02467" ixy="0" ixz="0" iyy="0.02467" iyz="0" izz="0.04411"/>
    </inertial>
    <visual>
      <origin rpy="1.57079632679 0 0" xyz="0 0 0"/>
      <geometry>
        <mesh filename="assets/ridgeback_description/meshes/wheel.stl"/>
      </geometry>
      <material name="black"/>
    </visual>
    <collision>
      <origin rpy="1.57079632679 0 0" xyz="0 0 0"/>
      <geometry>
        <cylinder length="0.079" radius="0.0759"/>
      </geometry>
    </collision>
  </link>
  <!-- <joint name="rear_left_wheel" type="continuous"> -->
  <joint name="rear_left_wheel" type="fixed">
    <parent link="rear_rocker_link"/>
    <child link="rear_left_wheel_link"/>
    <origin rpy="0 0 0" xyz="0 0.2755 0"/>
    <axis xyz="0 1 0"/>
  </joint>
  <link name="rear_right_wheel_link">
    <contact>
      <lateral_friction value="1.0"/>
      <rolling_friction value="0.0"/>
      <stiffness value="30000"/>
      <damping value="10000"/>
    </contact>
    <inertial>
      <origin rpy="0 0 0" xyz="0 0 0"/>
      <mass value="2.637"/>
      <!--<inertia ixx="3.3212e-3" ixy="0" ixz="0" iyy="6.6424e-3" iyz="0" izz="3.3212e-3"/>-->
      <inertia ixx="0.02467" ixy="0" ixz="0" iyy="0.02467" iyz="0" izz="0.04411"/>
    </inertial>
    <visual>
      <origin rpy="1.57079632679 0 0" xyz="0 0 0"/>
      <geometry>
        <mesh filename="assets/ridgeback_description/meshes/wheel.stl"/>
      </geometry>
      <material name="black"/>
    </visual>
    <collision>
      <origin rpy="1.57079632679 0 0" xyz="0 0 0"/>
      <geometry>
        <cylinder length="0.079" radius="0.0759"/>
      </geometry>
    </collision>
  </link>
  <!-- <joint name="rear_right_wheel" type="continuous"> -->
  <joint name="rear_right_wheel" type="fixed">
    <parent link="rear_rocker_link"/>
    <child link="rear_right_wheel_link"/>
    <origin rpy="0 0 0" xyz="0 -0.2755 0"/>
    <axis xyz="0 1 0"/>
  </joint>
  <link name="base_link">
    <inertial>
      <origin rpy="0 0 0" xyz="0 0 0"/>
      <mass value="1.0"/>
      <inertia ixx="1.0" ixy="0.0" ixz="0.0" iyy="1.0" iyz="0.0" izz="1.0"/>
    </inertial>
  </link>
  <joint name="base_link_joint" type="fixed">
    <origin rpy="0 0 0" xyz="0 0 0"/>
    <parent link="base_link"/>
    <child link="chassis_link"/>
  </joint>
  <link name="chassis_link">
    <visual>
      <origin rpy="0 0 0" xyz="0 0 0"/>
      <geometry>
        <mesh filename="assets/ridgeback_description/meshes/body.stl"/>
      </geometry>
      <material name="black"/>
    </visual> -->
    <collision>
      <origin xyz="0 0 0"/>
      <geometry>
        <mesh filename="assets/ridgeback_description/meshes/body-collision.stl"/>
      </geometry>
    </collision>
    <inertial>
      <origin rpy="1.57079632679 0 1.57079632679" xyz="0.012 0.002 0.067"/>
      <mass value="300.304"/>
      <inertia ixx="4.4744" ixy="0.03098" ixz="0.003647" iyy="7.1624" iyz="0.1228" izz="4.6155"/>
    </inertial>
  </link>
  <joint name="right_side_cover_link_joint" type="fixed">
    <origin rpy="0 0 0" xyz="0 0 0"/>
    <parent link="chassis_link"/>
    <child link="right_side_cover_link"/>
  </joint>
  <joint name="left_side_cover_link_joint" type="fixed">
    <origin rpy="0 0 0" xyz="0 0 0"/>
    <parent link="chassis_link"/>
    <child link="left_side_cover_link"/>
  </joint>
  <link name="left_side_cover_link">
    <inertial>
      <origin rpy="0 0 0" xyz="0 0 0"/>
      <mass value="1.0"/>
      <inertia ixx="1.0" ixy="0.0" ixz="0.0" iyy="1.0" iyz="0.0" izz="1.0"/>
    </inertial>
    <visual>
      <origin rpy="0 0 3.14159265359" xyz="0 0 0"/>
      <geometry>
        <mesh filename="assets/ridgeback_description/meshes/side-cover.stl"/>
      </geometry>
      <material name="yellow"/>
    </visual>
  </link>
  <link name="right_side_cover_link">
    <inertial>
      <origin rpy="0 0 0" xyz="0 0 0"/>
      <mass value="1.0"/>
      <inertia ixx="1.0" ixy="0.0" ixz="0.0" iyy="1.0" iyz="0.0" izz="1.0"/>
    </inertial>
    <visual>
      <origin rpy="0 0 0" xyz="0 0 0"/>
      <geometry>
        <mesh filename="assets/ridgeback_description/meshes/side-cover.stl"/>
      </geometry>
      <material name="yellow"/>
    </visual>
  </link>
  <joint name="front_cover_link_joint" type="fixed">
    <origin rpy="0 0 0" xyz="0 0 0"/>
    <parent link="chassis_link"/>
    <child link="front_cover_link"/>
  </joint>
  <link name="front_cover_link">
    <inertial>
      <origin rpy="0 0 0" xyz="0 0 0"/>
      <mass value="1.0"/>
      <inertia ixx="1.0" ixy="0.0" ixz="0.0" iyy="1.0" iyz="0.0" izz="1.0"/>
    </inertial>
    <visual>
      <origin rpy="0 0 0" xyz="0 0 0"/>
      <geometry>
        <mesh filename="assets/ridgeback_description/meshes/end-cover.stl"/>
      </geometry>
      <material name="black"/>
    </visual>
  </link>
  <joint name="rear_cover_link_joint" type="fixed">
    <origin rpy="0 0 0" xyz="0 0 0"/>
    <parent link="chassis_link"/>
    <child link="rear_cover_link"/>
  </joint>
  <link name="rear_cover_link">
    <inertial>
      <origin rpy="0 0 0" xyz="0 0 0"/>
      <mass value="1.0"/>
      <inertia ixx="1.0" ixy="0.0" ixz="0.0" iyy="1.0" iyz="0.0" izz="1.0"/>
    </inertial>
    <visual>
      <origin rpy="0 0 3.14159265359" xyz="0 0 0"/>
      <geometry>
        <mesh filename="assets/ridgeback_description/meshes/end-cover.stl"/>
      </geometry>
      <material name="black"/>
    </visual>
  </link>
  <joint name="front_lights_link_joint" type="fixed">
    <origin rpy="0 0 0" xyz="0 0 0"/>
    <parent link="chassis_link"/>
    <child link="front_lights_link"/>
  </joint>
  <joint name="rear_lights_link_joint" type="fixed">
    <origin rpy="0 0 0" xyz="0 0 0"/>
    <parent link="chassis_link"/>
    <child link="rear_lights_link"/>
  </joint>
  <link name="front_lights_link">
    <inertial>
      <origin rpy="0 0 0" xyz="0 0 0"/>
      <mass value="1.0"/>
      <inertia ixx="1.0" ixy="0.0" ixz="0.0" iyy="1.0" iyz="0.0" izz="1.0"/>
    </inertial>
    <visual>
      <origin rpy="0 0 0" xyz="0 0 0"/>
      <geometry>
        <mesh filename="assets/ridgeback_description/meshes/lights.stl"/>
      </geometry>
      <material name="white"/>
    </visual>
  </link>
  <link name="rear_lights_link">
    <inertial>
      <origin rpy="0 0 0" xyz="0 0 0"/>
      <mass value="1.0"/>
      <inertia ixx="1.0" ixy="0.0" ixz="0.0" iyy="1.0" iyz="0.0" izz="1.0"/>
    </inertial>
    <visual>
      <origin rpy="0 0 3.14159265359" xyz="0 0 0"/>
      <geometry>
        <mesh filename="assets/ridgeback_description/meshes/lights.stl"/>
      </geometry>
      <material name="red"/>
    </visual>
  </link>
  <joint name="top_link_joint" type="fixed">
    <origin rpy="0 0 0" xyz="0 0 0"/>
    <parent link="chassis_link"/>
    <child link="top_link"/>
  </joint>
  <link name="top_link">
    <inertial>
      <origin rpy="0 0 0" xyz="0 0 0"/>
      <mass value="1.0"/>
      <inertia ixx="1.0" ixy="0.0" ixz="0.0" iyy="1.0" iyz="0.0" izz="1.0"/>
    </inertial>
    <visual>
      <origin rpy="0 0 0" xyz="0 0 0"/>
      <geometry>
        <mesh filename="assets/ridgeback_description/meshes/top.stl"/>
      </geometry>
      <material name="black"/>
    </visual>
    <collision>
      <origin rpy="0 0 0" xyz="0 0 0"/>
      <geometry>
        <mesh filename="assets/ridgeback_description/meshes/top.stl"/>
      </geometry>
    </collision>
  </link>
  <joint name="axle_joint" type="fixed">
    <origin rpy="0 0 0" xyz="0 0 0.05"/>
    <parent link="chassis_link"/>
    <child link="axle_link"/>
  </joint>
  <link name="axle_link">
    <inertial>
      <origin rpy="0 0 0" xyz="0 0 0"/>
      <mass value="1.0"/>
      <inertia ixx="1.0" ixy="0.0" ixz="0.0" iyy="1.0" iyz="0.0" izz="1.0"/>
    </inertial>
    <visual>
      <origin rpy="0 1.57079632679 0" xyz="0 0 0"/>
      <geometry>
        <mesh filename="assets/ridgeback_description/meshes/axle.stl"/>
      </geometry>
      <material name="black"/>
    </visual>
  </link>
  <link name="imu_link">
    <inertial>
      <mass value="0.001"/>
      <origin rpy="0 0 0" xyz="0 0 0"/>
      <inertia ixx="1e-09" ixy="0.0" ixz="0.0" iyy="1e-09" iyz="0.0" izz="1e-09"/>
    </inertial>
  </link>
  <joint name="imu_joint" type="fixed">
    <parent link="chassis_link"/>
    <child link="imu_link"/>
    <origin rpy="0 0 0" xyz="0.2085 -0.2902 0.1681"/>
  </joint>
  <link name="mid_mount">
    <inertial>
      <origin rpy="0 0 0" xyz="0 0 0"/>
      <mass value="1.0"/>
      <inertia ixx="1.0" ixy="0.0" ixz="0.0" iyy="1.0" iyz="0.0" izz="1.0"/>
    </inertial>
  </link>
  <joint name="mid_mount_joint" type="fixed">
    <parent link="base_link"/>
    <child link="mid_mount"/>
    <origin rpy="0 0 0" xyz="0 0 0.28"/>
  </joint>

  <link name="arch_link">
    <inertial>
      <origin rpy="0 0 0" xyz="0 0 0"/>
      <mass value="1.0"/>
      <inertia ixx="1.0" ixy="0.0" ixz="0.0" iyy="1.0" iyz="0.0" izz="1.0"/>
    </inertial>
  <visual>
    <origin rpy="1.570795 0 0" xyz="0.0 0.0 0.0"/>
    <geometry>
      <mesh filename="assets/ridgeback_description/meshes/tor11_mech.stl" />
    </geometry>
    <material name="light_grey"/>
  </visual>
  <collision>
    <origin rpy="1.570795 0 0" xyz="0.0 0.0 0.0"/>
    <geometry>
      <mesh filename="assets/ridgeback_description/meshes/tor11_mech.stl" />
    </geometry>
  </collision>
 </link>

<joint name="arch_joint" type="fixed">
  <origin xyz="0 0 0.278" rpy="0 0 1.57" />
  <parent link="top_link" />
  <child link="arch_link" />
</joint>

<!-- Join arm and arch link -->
<joint name="ur10_arm_base" type="fixed">
  <parent link="arch_link" />
  <child link="ur10_base_link" />
  <origin xyz="0.01 -0.27 0.375" rpy="0.0 0.0 1.570796" />
</joint>


<!-- common stuff -->
<material name="blackish">
  <color rgba="0.2 0.2 0.2 1"/>
</material>
<material name="LightGrey">
  <color rgba="0.7 0.7 0.7 1.0"/>
</material>
<material name="LightBlue">
  <color rgba="0.670 0.815 0.921 1.0"/>
</material>

<link name="ur10_base_link">
  <visual>
    <origin xyz="0 0 0" rpy="1.57 0 0"/>
    <geometry>
      <mesh filename="assets/ur_description/meshes/ur10/visual/Base.obj"/>
    </geometry>
    <material name="LightGrey"/>
  </visual>
  <collision>
    <geometry>
      <mesh filename="assets/ur_description/meshes/ur10/collision/base.stl"/>
    </geometry>
  </collision>
  <inertial>
    <mass value="4.0"/>
    <origin rpy="0 0 0" xyz="0.0 0.0 0.0"/>
    <inertia ixx="0.0061063308908" ixy="0.0" ixz="0.0" iyy="0.0061063308908" iyz="0.0" izz="0.01125"/>
  </inertial>
</link>
<joint name="shoulder_pan_joint" type="revolute">
  <parent link="ur10_base_link"/>
  <child link="shoulder_link"/>
  <origin rpy="0.0 0.0 0.0" xyz="0.0 0.0 0.1273"/>
  <axis xyz="0 0 1"/>
  <limit effort="330.0" lower="-6.2831853" upper="6.2831853" velocity="2.16"/>
  <dynamics damping="0.0" friction="0.0"/>
</joint>
<link name="shoulder_link">
  <visual>
    <origin xyz="0 0 0" rpy="1.57 0 0"/>
    <geometry>
      <mesh filename="assets/ur_description/meshes/ur10/visual/Shoulder.obj"/>
    </geometry>
    <material name="LightGrey"/>
  </visual>
  <collision>
    <geometry>
      <mesh filename="assets/ur_description/meshes/ur10/collision/shoulder.stl"/>
    </geometry>
  </collision>
  <inertial>
    <mass value="7.778"/>
    <origin rpy="0 0 0" xyz="0.0 0.0 0.0"/>
    <inertia ixx="0.0314743125769" ixy="0.0" ixz="0.0" iyy="0.0314743125769" iyz="0.0" izz="0.021875625"/>
  </inertial>
</link>
<joint name="shoulder_lift_joint" type="revolute">
  <parent link="shoulder_link"/>
  <child link="upper_arm_link"/>
  <origin rpy="0.0 1.570796325 0.0" xyz="0.0 0.220941 0.0"/>
  <axis xyz="0 1 0"/>
  <limit effort="330.0" lower="-6.2831853" upper="6.2831853" velocity="2.16"/>
  <dynamics damping="0.0" friction="0.0"/>
</joint>
<link name="upper_arm_link">
  <visual>
    <origin xyz="0 0 0" rpy="1.57 0 0"/>
    <geometry>
      <mesh filename="assets/ur_description/meshes/ur10/visual/UpperArm.obj"/>
    </geometry>
    <material name="LightGrey"/>
  </visual>
  <collision>
    <geometry>
      <mesh filename="assets/ur_description/meshes/ur10/collision/upper_arm.stl"/>
    </geometry>
  </collision>
  <inertial>
    <mass value="12.93"/>
    <origin rpy="0 0 0" xyz="0.0 0.0 0.306"/>
    <inertia ixx="0.421753803798" ixy="0.0" ixz="0.0" iyy="0.421753803798" iyz="0.0" izz="0.036365625"/>
  </inertial>
</link>
<joint name="elbow_joint" type="revolute">
  <parent link="upper_arm_link"/>
  <child link="forearm_link"/>
  <origin rpy="0.0 0.0 0.0" xyz="0.0 -0.1719 0.612"/>
  <axis xyz="0 1 0"/>
  <limit effort="150.0" lower="-6.2831853" upper="6.2831853" velocity="3.15"/>
  <dynamics damping="0.0" friction="0.0"/>
</joint>
<link name="forearm_link">
  <visual>
    <origin xyz="0 0 0" rpy="1.57 0 0"/>
    <geometry>
      <mesh filename="assets/ur_description/meshes/ur10/visual/Forearm.obj"/>
    </geometry>
    <material name="LightGrey"/>
  </visual>
  <collision>
    <geometry>
      <mesh filename="assets/ur_description/meshes/ur10/collision/forearm.stl"/>
    </geometry>
  </collision>
  <inertial>
    <mass value="3.87"/>
    <origin rpy="0 0 0" xyz="0.0 0.0 0.28615"/>
    <inertia ixx="0.111069694097" ixy="0.0" ixz="0.0" iyy="0.111069694097" iyz="0.0" izz="0.010884375"/>
  </inertial>
</link>
<joint name="wrist_1_joint" type="revolute">
  <parent link="forearm_link"/>
  <child link="wrist_1_link"/>
  <origin rpy="0.0 1.570796325 0.0" xyz="0.0 0.0 0.5723"/>
  <axis xyz="0 1 0"/>
  <limit effort="54.0" lower="-6.2831853" upper="6.2831853" velocity="3.2"/>
  <dynamics damping="0.0" friction="0.0"/>
</joint>
<link name="wrist_1_link">
  <visual>
    <origin xyz="0 0 0" rpy="1.57 0 0"/>
    <geometry>
      <mesh filename="assets/ur_description/meshes/ur10/visual/Wrist1.obj"/>
    </geometry>
    <material name="LightBlue"/>
  </visual>
  <collision>
    <geometry>
      <mesh filename="assets/ur_description/meshes/ur10/collision/wrist_1.stl"/>
    </geometry>
  </collision>
  <inertial>
    <mass value="1.96"/>
    <origin rpy="0 0 0" xyz="0.0 0.0 0.0"/>
    <inertia ixx="0.0051082479567" ixy="0.0" ixz="0.0" iyy="0.0051082479567" iyz="0.0" izz="0.0055125"/>
  </inertial>
</link>
<joint name="wrist_2_joint" type="revolute">
  <parent link="wrist_1_link"/>
  <child link="wrist_2_link"/>
  <origin rpy="0.0 0.0 0.0" xyz="0.0 0.1149 0.0"/>
  <axis xyz="0 0 1"/>
  <limit effort="54.0" lower="-6.2831853" upper="6.2831853" velocity="3.2"/>
  <dynamics damping="0.0" friction="0.0"/>
</joint>
<link name="wrist_2_link">
  <visual>
    <origin xyz="0 0 0" rpy="1.57 0 0"/>
    <geometry>
      <mesh filename="assets/ur_description/meshes/ur10/visual/Wrist2.obj"/>
    </geometry>
    <material name="LightGrey"/>
  </visual>
  <collision>
    <geometry>
      <mesh filename="assets/ur_description/meshes/ur10/collision/wrist_2.stl"/>
    </geometry>
  </collision>
  <inertial>
    <mass value="1.96"/>
    <origin rpy="0 0 0" xyz="0.0 0.0 0.0"/>
    <inertia ixx="0.0051082479567" ixy="0.0" ixz="0.0" iyy="0.0051082479567" iyz="0.0" izz="0.0055125"/>
  </inertial>
</link>
<joint name="wrist_3_joint" type="revolute">
  <parent link="wrist_2_link"/>
  <child link="wrist_3_link"/>
  <origin rpy="0.0 0.0 0.0" xyz="0.0 0.0 0.1157"/>
  <axis xyz="0 1 0"/>
<!-- removed these joint limits since they often limit the final wrist joint in surprising and unhelpful ways -->
<!--  <limit effort="54.0" lower="-6.2831853" upper="6.2831853" velocity="3.2"/>-->
  <limit effort="54.0" velocity="3.2"/>
  <dynamics damping="0.0" friction="0.0"/>
</joint>
<link name="wrist_3_link">
  <visual>
    <origin xyz="0 0 0" rpy="1.57 0 0"/>
    <geometry>
      <mesh filename="assets/ur_description/meshes/ur10/visual/Wrist3.obj"/>
    </geometry>
    <material name="LightBlue"/>
  </visual>
  <collision>
    <geometry>
      <mesh filename="assets/ur_description/meshes/ur10/collision/wrist_3.stl"/>
    </geometry>
  </collision>
  <inertial>
    <mass value="0.202"/>
    <origin rpy="0 0 0" xyz="0.0 0.0 0.0"/>
    <inertia ixx="0.000526462289415" ixy="0.0" ixz="0.0" iyy="0.000526462289415" iyz="0.0" izz="0.000568125"/>
  </inertial>
</link>
<joint name="ee_fixed_joint" type="fixed">
  <parent link="wrist_3_link"/>
  <child link="ee_link"/>
  <origin rpy="0.0 0.0 1.570796325" xyz="0.0 0.0922 0.0"/>
</joint>
<link name="ee_link">
  <inertial>
      <origin rpy="0 0 0" xyz="0 0 0"/>
      <mass value="1.0"/>
      <inertia ixx="1.0" ixy="0.0" ixz="0.0" iyy="1.0" iyz="0.0" izz="1.0"/>
    </inertial>
  <collision>
    <geometry>
      <box size="0.01 0.01 0.01"/>
    </geometry>
    <origin rpy="0 0 0" xyz="-0.01 0 0"/>
  </collision>
</link>

<!-- Gripper -->
   <joint name="panda_hand_joint" type="fixed">
    <parent link="ee_link"/>
    <child link="panda_hand"/>
<!--    <origin rpy="0 0 -0.785398163397" xyz="0 0 0"/>-->
    <origin rpy="0 1.5707 0" xyz="0 0 0"/>
  </joint>
<link name="panda_hand">
  	<inertial>
      <origin rpy="0 0 0" xyz="0 0 0.04"/>
       <mass value=".81"/>
<!--       <mass value=".1"/>-->
       <inertia ixx="0.1" ixy="0" ixz="0" iyy="0.1" iyz="0" izz="0.1"/>
    </inertial>
    <visual>
      <geometry>
        <mesh filename="assets/panda_meshes/visual/hand.obj"/>
      </geometry>
      <material name="panda_white">
        <color rgba="1. 1. 1. 1."/>
      </material>
    </visual>
    <collision>
      <geometry>
        <mesh filename="assets/panda_meshes/collision/hand.obj"/>
      </geometry>
      <material name="panda_white"/>
    </collision>
  </link>
  <link name="panda_leftfinger">
       <contact>
      <friction_anchor/>
      <stiffness value="30000.0"/>
      <damping value="1000.0"/>
      <spinning_friction value="0.1"/>
      <lateral_friction value="1.0"/>
    </contact>
  	<inertial>
      <origin rpy="0 0 0" xyz="0 0.01 0.02"/>
       <mass value="0.1"/>
       <inertia ixx="0.1" ixy="0" ixz="0" iyy="0.1" iyz="0" izz="0.1"/>
    </inertial>
    <visual>
      <geometry>
        <mesh filename="assets/panda_meshes/visual/finger.obj"/>
      </geometry>
      <material name="panda_white"/>
    </visual>
    <collision>
      <geometry>
        <mesh filename="assets/panda_meshes/collision/finger.obj"/>
      </geometry>
      <material name="panda_white"/>
    </collision>
  </link>
  <link name="panda_rightfinger">
        <contact>
      <friction_anchor/>
      <stiffness value="30000.0"/>
      <damping value="1000.0"/>
      <spinning_friction value="0.1"/>
      <lateral_friction value="1.0"/>
    </contact>

  	<inertial>
      <origin rpy="0 0 0" xyz="0 -0.01 0.02"/>
       <mass value="0.1"/>
       <inertia ixx="0.1" ixy="0" ixz="0" iyy="0.1" iyz="0" izz="0.1"/>
    </inertial>
    <visual>
      <origin rpy="0 0 3.14159265359" xyz="0 0 0"/>
      <geometry>
        <mesh filename="assets/panda_meshes/visual/finger.obj"/>
      </geometry>
      <material name="panda_white"/>
    </visual>
    <collision>
      <origin rpy="0 0 3.14159265359" xyz="0 0 0"/>
      <geometry>
        <mesh filename="assets/panda_meshes/collision/finger.obj"/>
      </geometry>
      <material name="panda_white"/>
    </collision>
  </link>
  <joint name="panda_finger_joint1" type="prismatic">
    <parent link="panda_hand"/>
    <child link="panda_leftfinger"/>
    <origin rpy="0 0 0" xyz="0 0 0.0584"/>
    <axis xyz="0 1 0"/>
    <limit effort="20" lower="0.0" upper="0.04" velocity="0.2"/>
  </joint>
  <joint name="panda_finger_joint2" type="prismatic">
    <parent link="panda_hand"/>
    <child link="panda_rightfinger"/>
    <origin rpy="0 0 0" xyz="0 0 0.0584"/>
    <axis xyz="0 -1 0"/>
    <limit effort="20" lower="0.0" upper="0.04" velocity="0.2"/>
    <mimic joint="panda_finger_joint1"/>
  </joint>
   <link name="panda_grasptarget">
     <visual>
    <material name="blackish"/>
    <geometry>
      <box size=".004 .004 .004"/>
    </geometry>
  </visual>
    <inertial>
      <origin rpy="0 0 0" xyz="0 0 0"/>
       <mass value="0.0"/>
       <inertia ixx="0.1" ixy="0" ixz="0" iyy="0.1" iyz="0" izz="0.1"/>
    </inertial>
   </link>
   <joint name="panda_grasptarget_hand" type="fixed">
    <parent link="panda_hand"/>
    <child link="panda_grasptarget"/>
    <origin rpy="0 0 1.5708" xyz="0 0 .105"/>
  </joint>

<!-- fix for broken jacobian calculations -->
<link name="world"/>
 <joint name="world_joint" type="fixed">
   <parent link="world"/>
   <child link="base_link"/>
   <origin rpy="0.0 0.0 0.0" xyz="0.0 0.0 0.0"/>
 </joint>

<!-- tool frame -->
<link name="tool_link">
  <inertial>
      <origin rpy="0 0 0" xyz="0 0 0"/>
      <mass value="0.0"/>
      <inertia ixx="1.0" ixy="0.0" ixz="0.0" iyy="1.0" iyz="0.0" izz="1.0"/>
    </inertial>
  <visual>
    <material name="blackish"/>
    <geometry>
      <box size=".0001 .0001 .0001"/>
    </geometry>
  </visual>
</link>
<joint name="tool_joint" type="fixed">
  <parent link="ee_link"/>
  <child link="tool_link"/>
  <origin rpy="-1.570796325 0 -1.570796325" xyz="0.1 0.0 0.0"/>
</joint>

<!-- add a link for the camera mount -->
<!--<link name="cam_mount">-->
<!--  <inertial>-->
<!--    <origin rpy="0 0 0" xyz="0 0 0"/>-->
<!--    <mass value="0.000000001"/>-->
<!--    <inertia ixx="1.0" ixy="0.0" ixz="0.0" iyy="1.0" iyz="0.0" izz="1.0"/>-->
<!--  </inertial>-->
<!--  <visual>-->
<!--    <origin rpy="0 0 0" xyz="0.0 0.0 0.0"/>-->
<!--    <geometry>-->
<!--      <box size=".23 .02 .02" />-->
<!--    </geometry>-->
<!--    <material name="light_grey"/>-->
<!--  </visual>-->
<!--</link>-->

<!--<joint name="arch_cam_mount_joint" type="fixed">-->
<!--  <parent link="arch_link" />-->
<!--  <child link="cam_mount" />-->
<!--  <origin xyz=".365 .475 .822" rpy="0 0 0"/>-->
<!--</joint>-->



</robot>

