<?xml version="1.0" ?>
<!-- =================================================================================== -->
<!-- |    This document was autogenerated by xacro from ur10_robot.urdf.xacro          | -->
<!-- |    EDITING THIS FILE BY HAND IS NOT RECOMMENDED                                 | -->
<!-- =================================================================================== -->
<robot name="ur10" xmlns:xacro="http://www.ros.org/wiki/xacro">
  <!-- common stuff -->
  <material name="blackish">
    <color rgba="0.2 0.2 0.2 1"/>
  </material>
  <material name="LightGrey">
    <color rgba="0.7 0.7 0.7 1.0"/>
  </material>
  <material name="LightBlue">
    <color rgba="0.670 0.815 0.921 1.0"/>
  </material>
  <!-- ur10 arm -->
  <link name="world"/>
  <joint name="world_joint" type="fixed">
    <parent link="world"/>
    <child link="base_link"/>
    <origin rpy="0.0 0.0 0.0" xyz="0.0 0.0 0.0"/>
  </joint>

  <link name="base_link">
    <visual>
      <origin xyz="0 0 0" rpy="1.57 0 0"/>
      <geometry>
        <mesh filename="assets/ur_description/meshes/ur10/visual/Base.obj"/>
      </geometry>
      <material name="LightGrey"/>
    </visual>
    <collision>
      <geometry>
        <mesh filename="assets/ur_description/meshes/ur10/collision/base.stl"/>
      </geometry>
    </collision>
    <inertial>
      <mass value="4.0"/>
      <origin rpy="0 0 0" xyz="0.0 0.0 0.0"/>
      <inertia ixx="0.0061063308908" ixy="0.0" ixz="0.0" iyy="0.0061063308908" iyz="0.0" izz="0.01125"/>
    </inertial>
  </link>
  <joint name="shoulder_pan_joint" type="revolute">
    <parent link="base_link"/>
    <child link="shoulder_link"/>
    <origin rpy="0.0 0.0 0.0" xyz="0.0 0.0 0.1273"/>
    <axis xyz="0 0 1"/>
    <limit effort="330.0" lower="-6.2831853" upper="6.2831853" velocity="2.16"/>
    <dynamics damping="0.0" friction="0.0"/>
  </joint>
  <link name="shoulder_link">
    <visual>
      <origin xyz="0 0 0" rpy="1.57 0 0"/>
      <geometry>
        <mesh filename="assets/ur_description/meshes/ur10/visual/Shoulder.obj"/>
      </geometry>
      <material name="LightGrey"/>
    </visual>
    <collision>
      <geometry>
        <mesh filename="assets/ur_description/meshes/ur10/collision/shoulder.stl"/>
      </geometry>
    </collision>
    <inertial>
      <mass value="7.778"/>
      <origin rpy="0 0 0" xyz="0.0 0.0 0.0"/>
      <inertia ixx="0.0314743125769" ixy="0.0" ixz="0.0" iyy="0.0314743125769" iyz="0.0" izz="0.021875625"/>
    </inertial>
  </link>
  <joint name="shoulder_lift_joint" type="revolute">
    <parent link="shoulder_link"/>
    <child link="upper_arm_link"/>
    <origin rpy="0.0 1.570796325 0.0" xyz="0.0 0.220941 0.0"/>
    <axis xyz="0 1 0"/>
    <limit effort="330.0" lower="-6.2831853" upper="6.2831853" velocity="2.16"/>
    <dynamics damping="0.0" friction="0.0"/>
  </joint>
  <link name="upper_arm_link">
    <visual>
      <origin xyz="0 0 0" rpy="1.57 0 0"/>
      <geometry>
        <mesh filename="assets/ur_description/meshes/ur10/visual/UpperArm.obj"/>
      </geometry>
      <material name="LightGrey"/>
    </visual>
    <collision>
      <geometry>
        <mesh filename="assets/ur_description/meshes/ur10/collision/upper_arm.stl"/>
      </geometry>
    </collision>
    <inertial>
      <mass value="12.93"/>
      <origin rpy="0 0 0" xyz="0.0 0.0 0.306"/>
      <inertia ixx="0.421753803798" ixy="0.0" ixz="0.0" iyy="0.421753803798" iyz="0.0" izz="0.036365625"/>
    </inertial>
  </link>
  <joint name="elbow_joint" type="revolute">
    <parent link="upper_arm_link"/>
    <child link="forearm_link"/>
    <origin rpy="0.0 0.0 0.0" xyz="0.0 -0.1719 0.612"/>
    <axis xyz="0 1 0"/>
    <limit effort="150.0" lower="-6.2831853" upper="6.2831853" velocity="3.15"/>
    <dynamics damping="0.0" friction="0.0"/>
  </joint>
  <link name="forearm_link">
    <visual>
      <origin xyz="0 0 0" rpy="1.57 0 0"/>
      <geometry>
        <mesh filename="assets/ur_description/meshes/ur10/visual/Forearm.obj"/>
      </geometry>
      <material name="LightGrey"/>
    </visual>
    <collision>
      <geometry>
        <mesh filename="assets/ur_description/meshes/ur10/collision/forearm.stl"/>
      </geometry>
    </collision>
    <inertial>
      <mass value="3.87"/>
      <origin rpy="0 0 0" xyz="0.0 0.0 0.28615"/>
      <inertia ixx="0.111069694097" ixy="0.0" ixz="0.0" iyy="0.111069694097" iyz="0.0" izz="0.010884375"/>
    </inertial>
  </link>
  <joint name="wrist_1_joint" type="revolute">
    <parent link="forearm_link"/>
    <child link="wrist_1_link"/>
    <origin rpy="0.0 1.570796325 0.0" xyz="0.0 0.0 0.5723"/>
    <axis xyz="0 1 0"/>
    <limit effort="54.0" lower="-6.2831853" upper="6.2831853" velocity="3.2"/>
    <dynamics damping="0.0" friction="0.0"/>
  </joint>
  <link name="wrist_1_link">
    <visual>
      <origin xyz="0 0 0" rpy="1.57 0 0"/>
      <geometry>
        <mesh filename="assets/ur_description/meshes/ur10/visual/Wrist1.obj"/>
      </geometry>
      <material name="LightBlue"/>
    </visual>
    <collision>
      <geometry>
        <mesh filename="assets/ur_description/meshes/ur10/collision/wrist_1.stl"/>
      </geometry>
    </collision>
    <inertial>
      <mass value="1.96"/>
      <origin rpy="0 0 0" xyz="0.0 0.0 0.0"/>
      <inertia ixx="0.0051082479567" ixy="0.0" ixz="0.0" iyy="0.0051082479567" iyz="0.0" izz="0.0055125"/>
    </inertial>
  </link>
  <joint name="wrist_2_joint" type="revolute">
    <parent link="wrist_1_link"/>
    <child link="wrist_2_link"/>
    <origin rpy="0.0 0.0 0.0" xyz="0.0 0.1149 0.0"/>
    <axis xyz="0 0 1"/>
    <limit effort="54.0" lower="-6.2831853" upper="6.2831853" velocity="3.2"/>
    <dynamics damping="0.0" friction="0.0"/>
  </joint>
  <link name="wrist_2_link">
    <visual>
      <origin xyz="0 0 0" rpy="1.57 0 0"/>
      <geometry>
        <mesh filename="assets/ur_description/meshes/ur10/visual/Wrist2.obj"/>
      </geometry>
      <material name="LightGrey"/>
    </visual>
    <collision>
      <geometry>
        <mesh filename="assets/ur_description/meshes/ur10/collision/wrist_2.stl"/>
      </geometry>
    </collision>
    <inertial>
      <mass value="1.96"/>
      <origin rpy="0 0 0" xyz="0.0 0.0 0.0"/>
      <inertia ixx="0.0051082479567" ixy="0.0" ixz="0.0" iyy="0.0051082479567" iyz="0.0" izz="0.0055125"/>
    </inertial>
  </link>
  <joint name="wrist_3_joint" type="revolute">
    <parent link="wrist_2_link"/>
    <child link="wrist_3_link"/>
    <origin rpy="0.0 0.0 0.0" xyz="0.0 0.0 0.1157"/>
    <axis xyz="0 1 0"/>
    <limit effort="54.0" lower="-6.2831853" upper="6.2831853" velocity="3.2"/>
    <dynamics damping="0.0" friction="0.0"/>
  </joint>
  <link name="wrist_3_link">
    <visual>
      <origin xyz="0 0 0" rpy="1.57 0 0"/>
      <geometry>
        <mesh filename="assets/ur_description/meshes/ur10/visual/Wrist3.obj"/>
      </geometry>
      <material name="LightBlue"/>
    </visual>
    <collision>
      <geometry>
        <mesh filename="assets/ur_description/meshes/ur10/collision/wrist_3.stl"/>
      </geometry>
    </collision>
    <inertial>
      <mass value="0.202"/>
      <origin rpy="0 0 0" xyz="0.0 0.0 0.0"/>
      <inertia ixx="0.000526462289415" ixy="0.0" ixz="0.0" iyy="0.000526462289415" iyz="0.0" izz="0.000568125"/>
    </inertial>
  </link>

  <joint name="ee_fixed_joint" type="fixed">
    <parent link="wrist_3_link"/>
    <child link="ee_link"/>
    <origin rpy="0.0 0.0 1.570796325" xyz="0.0 0.0922 0.0"/>
  </joint>

  <link name="ee_link">
    <collision>
      <geometry>
        <box size="0.01 0.01 0.01"/>
      </geometry>
      <origin rpy="0 0 0" xyz="-0.01 0 0"/>
    </collision>
  </link>

  <joint name="pr2_left_gripper_joint" type="revolute">
    <axis xyz="0 0 1"/>
    <limit effort="1000.0" lower="-2.0" upper="0.548" velocity="0.5"/>
    <parent link="ee_link"/>
    <child link="left_gripper"/>
    <origin rpy="0 0 0" xyz="0 0.01 0"/>
  </joint>

<link name="left_gripper">
  <contact>
    <lateral_friction value="5.0"/>
    <spinning_friction value="0.1"/>
  </contact>
  <visual>
    <origin rpy="0.0 0 0" xyz="0 0 0"/>
    <material name="blackish"/>
    <geometry>
      <mesh filename="assets/pr2_gripper/l_finger_collision.stl"/>
    </geometry>
  </visual>
  <collision>
    <origin rpy="0.0 0 0" xyz="0 0 0"/>
    <geometry>
      <mesh filename="assets/pr2_gripper/l_finger_collision.stl" scale=".9 .9 .9"/>
    </geometry>
  </collision>
  <inertial>
    <mass value="0.5"/>
    <inertia ixx="1.0" ixy="0.0" ixz="0.0" iyy="1.0" iyz="0.0" izz="1.0"/>
  </inertial>
 </link>

 <joint name="left_tip_joint" type="fixed">
  <parent link="left_gripper"/>
  <child link="left_tip"/>
</joint>

<link name="left_tip">
  <contact>
    <lateral_friction value="5.0"/>
    <spinning_friction value="0.1"/>
  </contact>
  <visual>
    <origin rpy="0.0 0 0" xyz="0.09137 0.00495 0"/>
    <material name="blackish"/>
    <geometry>
      <mesh filename="assets/pr2_gripper/l_finger_tip.stl"/>
    </geometry>
  </visual>
  <collision>
    <geometry>
      <box size=".03 .03 .02"/>
    </geometry>
    <origin rpy="0.0 0.0 0" xyz="0.105 0.00495 0"/>
  </collision>
  <inertial>
    <mass value="0.1"/>
    <inertia ixx="1.0" ixy="0.0" ixz="0.0" iyy="1.0" iyz="0.0" izz="1.0"/>
  </inertial>
</link>

<joint name="pr2_right_gripper_joint" type="revolute">
  <axis xyz="0 0 -1"/>
  <limit effort="1000.0" lower="0.0" upper="0.548" velocity="0.5"/>
  <origin rpy="0 0 0" xyz="0 -0.01 0"/>
  <parent link="ee_link"/>
  <child link="right_gripper"/>
</joint>

<link name="right_gripper">
  <contact>
    <lateral_friction value="5.0"/>
    <spinning_friction value="0.3"/>
  </contact>
  <visual>
    <origin rpy="-3.1415 0 0" xyz="0 0 0"/>
    <material name="blackish"/>
    <geometry>
      <mesh filename="assets/pr2_gripper/l_finger_collision.stl"/>
    </geometry>
  </visual>
       <collision>
    <origin rpy="-3.1415 0 0" xyz="0 0 0"/>
    <geometry>
      <mesh filename="assets/pr2_gripper/l_finger_collision.stl"/>
    </geometry>
  </collision>
  <inertial>
    <mass value="0.05"/>
    <inertia ixx="1.0" ixy="0.0" ixz="0.0" iyy="1.0" iyz="0.0" izz="1.0"/>
  </inertial>
</link>

<joint name="right_tip_joint" type="fixed">
  <parent link="right_gripper"/>
  <child link="right_tip"/>
</joint>

<link name="right_tip">
  <contact>
    <lateral_friction value="5.0"/>
    <spinning_friction value="0.2"/>
  </contact>
  <visual>
    <origin rpy="-3.1415 0 0" xyz="0.09137 0.00495 0"/>
    <material name="blackish"/>
    <geometry>
      <mesh filename="assets/pr2_gripper/l_finger_tip.stl"/>
    </geometry>
  </visual>
  <collision>
    <geometry>
      <box size=".03 .03 .02"/>
    </geometry>
    <origin rpy="-3.1415 0 0" xyz="0.105 0.00495 0"/>
  </collision>
  <inertial>
    <mass value="0.05"/>
    <inertia ixx="1.0" ixy="0.0" ixz="0.0" iyy="1.0" iyz="0.0" izz="1.0"/>
  </inertial>
</link>

</robot>
