<?xml version="1.0" ?>
<!--This file the kuka gripper only, as seen in https://www.youtube.com/watch?v=JzmcRT5rc3c -->
<sdf version='1.6'>
  <world name='default'>
  <model name='kuka_gripper_only'>
    <link name='base_link'>
      <pose frame=''>0 0 1.305 1.5707 -0 0</pose>
      <inertial>
        <pose frame=''>0 0 0 0 -0 0</pose>
        <mass>1.2</mass>
        <inertia>
          <ixx>1</ixx>
          <ixy>0</ixy>
          <ixz>0</ixz>
          <iyy>1</iyy>
          <iyz>0</iyz>
          <izz>1</izz>
        </inertia>
      </inertial>
      <!--
      <visual name='base_link_visual'>
        <pose frame=''>0 0 0 0 0 0</pose>
        <geometry>
		  <box>
		     <size>0.05 0.05 0.1 </size>
		  </box>
        </geometry>
        <material>
          <ambient>1 0 0 1</ambient>
          <diffuse>0.6 0.6 0.6 1</diffuse>
          <specular>0.5 0.5 0.5 1</specular>
          <emissive>0 0 0 0</emissive>
        </material>
      </visual>
      -->
    </link>

    <joint name='base_left_finger_joint' type='revolute'>
      <parent>base_link</parent>
      <child>left_finger</child>
      <axis>
        <xyz>0 1 0</xyz>
        <limit>
          <lower>-10.4</lower>
          <upper>10.01</upper>
          <effort>100</effort>
          <velocity>0</velocity>
        </limit>
        <dynamics>
          <damping>0</damping>
          <friction>0</friction>
          <spring_reference>0</spring_reference>
          <spring_stiffness>0</spring_stiffness>
        </dynamics>
      </axis>
    </joint>
    <link name='left_finger'>
      <pose frame=''>0 0.024 1.35 0 -0.05 0</pose>
      <!-- <pose frame=''>0 0.024 1.305 0 -0.05 0</pose> -->
      <inertial>
        <pose frame=''>0 0 0.04 0 0 0</pose>
        <mass>0.1</mass>
        <inertia>
          <ixx>0.1</ixx>
          <ixy>0</ixy>
          <ixz>0</ixz>
          <iyy>0.1</iyy>
          <iyz>0</iyz>
          <izz>0.1</izz>
        </inertia>
      </inertial>
      <visual name='left_finger_visual'>
        <pose frame=''>0 0 0.04 0 0 0</pose>
        <geometry>
          <box>
            <size>0.01 0.01 0.08</size>
          </box>
        </geometry>
        <material>
          <ambient>1 0 0 1</ambient>
          <diffuse>0.6 0.6 0.6 1</diffuse>
          <specular>0.5 0.5 0.5 1</specular>
          <emissive>0 0 0 0</emissive>
        </material>
      </visual>
    </link>
    <joint name='left_finger_base_joint' type='fixed'>
      <parent>left_finger</parent>
      <child>left_finger_base</child>
    </joint>
    <link name='left_finger_base'>
      <pose frame=''>-0.005 0.024 1.43 0 -0.3 0</pose>
      <!-- <pose frame=''>-0.005 0.024 1.385 0 -0.3 0</pose> -->
      <inertial>
        <pose frame=''>-0.003 0 0.04 0 0 0 </pose>
        <mass>0.2</mass>
        <inertia>
          <ixx>0.1</ixx>
          <ixy>0</ixy>
          <ixz>0</ixz>
          <iyy>0.1</iyy>
          <iyz>0</iyz>
          <izz>0.1</izz>
        </inertia>
      </inertial>
      <visual name='left_finger_base_visual'>
        <pose frame=''>0 0 0 0 0 0 </pose>
        <geometry>
          <mesh>
            <scale>1 1 1 </scale>
            <uri>meshes/finger_base_left.stl</uri>
          </mesh>
        </geometry>
        <material>
          <ambient>1 0 0 1</ambient>
          <diffuse>0.6 0.6 0.6 1</diffuse>
          <specular>0.5 0.5 0.5 1</specular>
          <emissive>0 0 0 0</emissive>
        </material>
      </visual>
      <collision name='left_finger_base_collision'>
        <pose frame=''>0 0 0 0 0 0 </pose>
        <geometry>
          <mesh>
            <scale>1 1 1 </scale>
            <uri>meshes/finger_base_left.stl</uri>
          </mesh>
        </geometry>
      </collision>
    </link>
    <joint name='left_base_tip_joint' type='revolute'>
      <parent>left_finger_base</parent>
      <child>left_finger_tip</child>
      <axis>
        <xyz>0 1 0</xyz>
        <limit>
          <lower>-10.1</lower>
          <upper>10.3</upper>
          <effort>0</effort>
          <velocity>0</velocity>
        </limit>
        <dynamics>
          <damping>0</damping>
          <friction>0</friction>
          <spring_reference>0</spring_reference>
          <spring_stiffness>0</spring_stiffness>
        </dynamics>
      </axis>
    </joint>
    <link name='left_finger_tip'>
      <contact>
        <lateral_friction>0.8</lateral_friction>
        <spinning_friction>1.0</spinning_friction>
      </contact>
      <pose frame=''>-0.02 0.024 1.49 0 0.2 0</pose>
      <!-- <pose frame=''>-0.02 0.024 1.445 0 0.2 0</pose> -->
      <inertial>
        <pose frame=''>-0.005 0 0.026 0 0 0 </pose>
        <mass>0.2</mass>
        <inertia>
          <ixx>0.1</ixx>
          <ixy>0</ixy>
          <ixz>0</ixz>
          <iyy>0.1</iyy>
          <iyz>0</iyz>
          <izz>0.1</izz>
        </inertia>
      </inertial>
      <visual name='left_finger_tip_visual'>
        <pose frame=''>0 0 0 0 0 0</pose>
        <geometry>
          <mesh>
            <scale>1 1 1 </scale>
            <uri>meshes/finger_tip_left.stl</uri>
          </mesh>
        </geometry>
        <material>
          <ambient>1 0 0 1</ambient>
          <diffuse>0.6 0.6 0.6 1</diffuse>
          <specular>0.5 0.5 0.5 1</specular>
          <emissive>0 0 0 0</emissive>
        </material>
      </visual>
      <collision name='left_finger_tip_collision'>
        <pose frame=''>0 0 0 0 0 0</pose>
        <geometry>
          <mesh>
            <scale>1 1 1 </scale>
            <uri>meshes/finger_tip_left.stl</uri>
          </mesh>
        </geometry>
      </collision>
    </link>
    <joint name='base_right_finger_joint' type='revolute'>
      <parent>base_link</parent>
      <child>right_finger</child>
      <axis>
        <xyz>0 1 0</xyz>
        <limit>
          <lower>-10.01</lower>
          <upper>10.4</upper>
          <effort>100</effort>
          <velocity>0</velocity>
        </limit>
        <dynamics>
          <damping>0</damping>
          <friction>0</friction>
          <spring_reference>0</spring_reference>
          <spring_stiffness>0</spring_stiffness>
        </dynamics>
      </axis>
    </joint>
    <link name='right_finger'>
      <pose frame=''>0 0.024 1.35 0 0.05 0</pose>
      <!-- <pose frame=''>0 0.024 1.305 0 0.05 0</pose> -->
      <inertial>
        <pose frame=''>0 0 0.04 0 0 0</pose>
        <mass>0.1</mass>
        <inertia>
          <ixx>0.1</ixx>
          <ixy>0</ixy>
          <ixz>0</ixz>
          <iyy>0.1</iyy>
          <iyz>0</iyz>
          <izz>0.1</izz>
        </inertia>
      </inertial>
      <visual name='right_finger_visual'>
        <pose frame=''>0 0 0.04 0 0 0</pose>
        <geometry>
          <box>
            <size>0.01 0.01 0.08</size>
          </box>
        </geometry>
        <material>
          <ambient>1 0 0 1</ambient>
          <diffuse>0.6 0.6 0.6 1</diffuse>
          <specular>0.5 0.5 0.5 1</specular>
          <emissive>0 0 0 0</emissive>
        </material>
      </visual>
    </link>
    <joint name='right_finger_base_joint' type='fixed'>
      <parent>right_finger</parent>
      <child>right_finger_base</child>
    </joint>
    <link name='right_finger_base'>
      <pose frame=''>0.005 0.024 1.43 0 0.3 0</pose>
      <!-- <pose frame=''>0.005 0.024 1.385 0 0.3 0</pose> -->
      <inertial>
        <pose frame=''>0.003 0 0.04 0 0 0 </pose>
        <mass>0.2</mass>
        <inertia>
          <ixx>0.1</ixx>
          <ixy>0</ixy>
          <ixz>0</ixz>
          <iyy>0.1</iyy>
          <iyz>0</iyz>
          <izz>0.1</izz>
        </inertia>
      </inertial>
      <visual name='right_finger_base_visual'>
        <pose frame=''>0 0 0 0 0 0 </pose>
        <geometry>
          <mesh>
            <scale>1 1 1 </scale>
            <uri>meshes/finger_base_right.stl</uri>
          </mesh>
        </geometry>
        <material>
          <ambient>1 0 0 1</ambient>
          <diffuse>0.6 0.6 0.6 1</diffuse>
          <specular>0.5 0.5 0.5 1</specular>
          <emissive>0 0 0 0</emissive>
        </material>
      </visual>
      <collision name='right_finger_base_collision'>
        <pose frame=''>0 0 0 0 0 0 </pose>
        <geometry>
          <mesh>
            <scale>1 1 1 </scale>
            <uri>meshes/finger_base_right.stl</uri>
          </mesh>
        </geometry>
      </collision>
    </link>
    <joint name='right_base_tip_joint' type='revolute'>
      <parent>right_finger_base</parent>
      <child>right_finger_tip</child>
      <axis>
        <xyz>0 1 0</xyz>
        <limit>
          <lower>-10.3</lower>
          <upper>10.1</upper>
          <effort>0</effort>
          <velocity>0</velocity>
        </limit>
        <dynamics>
          <damping>0</damping>
          <friction>0</friction>
          <spring_reference>0</spring_reference>
          <spring_stiffness>0</spring_stiffness>
        </dynamics>
      </axis>
    </joint>
    <link name='right_finger_tip'>
      <contact>
        <lateral_friction>0.8</lateral_friction>
        <spinning_friction>1.0</spinning_friction>
      </contact>
      <pose frame=''>0.02 0.024 1.49 0 -0.2 0</pose>
      <!-- <pose frame=''>0.02 0.024 1.445 0 -0.2 0</pose> -->
      <inertial>
        <pose frame=''>0.005 0 0.026 0 0 0 </pose>
        <mass>0.2</mass>
        <inertia>
          <ixx>0.1</ixx>
          <ixy>0</ixy>
          <ixz>0</ixz>
          <iyy>0.1</iyy>
          <iyz>0</iyz>
          <izz>0.1</izz>
        </inertia>
      </inertial>
      <visual name='right_finger_visual'>
        <pose frame=''>0 0 0 0 0 0</pose>
        <geometry>
          <mesh>
            <scale>1 1 1 </scale>
            <uri>meshes/finger_tip_right.stl</uri>
          </mesh>
        </geometry>
        <material>
          <ambient>1 0 0 1</ambient>
          <diffuse>0.6 0.6 0.6 1</diffuse>
          <specular>0.5 0.5 0.5 1</specular>
          <emissive>0 0 0 0</emissive>
        </material>
      </visual>
      <collision name='right_finger_tip_collision'>
        <pose frame=''>0 0 0 0 0 0</pose>
        <geometry>
          <mesh>
            <scale>1 1 1 </scale>
            <uri>meshes/finger_tip_right.stl</uri>
          </mesh>
        </geometry>
      </collision>
    </link>
  </model>
</world>
</sdf>
